Workbook

Sheet OP 1
F1: OP | G1: FALSE
C2: ORDEM DE SEPARAÇÃO E PRODUTO ACABADO | F2: 26183/03
A5: PEDIDO | B5: -
A6: DATA | B6: Cliente | F6: VALIDADE
A7: 46205 | B7: =INDEX([1]Produtos!$G:$G,MATCH(B11,[1]Produtos!$C:$C,0)) -> MISS RÔSE | F7: ='ORDEM DE ENVASE'!B7 -> 47301
A9: PRODUTO
A10: SKU / Cod. Clien. | B10: Descrição do Produto | E10: Qtde | F10: Volume | G10: Dens.
A11: =INDEX([1]Produtos!$B:$B,MATCH(B11,[1]Produtos!$C:$C,0)) -> MRARBS10 | B11: BODY SPLASH AMBAR REAL 200ml | E11: 4608 | F11: =INDEX([1]Produtos!$E:$E,MATCH(B11,[1]Produtos!$C:$C,0))/1000 -> 0.215 | G11: 1
A12: =INDEX([1]Produtos!$O:$O,MATCH(B11,[1]Produtos!$C:$C,0)) -> MR157/E
A13: MATERIAL
A14: SKU | B14: Descrição do Material | E14: Quantidade | F14: Qtde. Separada
A15: - | B15: ="FORMULA "&B11 -> FORMULA BODY SPLASH AMBAR REAL 200ml | E15: =OF!G6 -> 990.72
A16: EMMRRT18 - MR | B16: ROTULO BODY SPLASH AMBAR REAL - (MISS ROSE) | E16: =E11 -> 4608
A17: EMSPFR03 | B17: FRASCO PET 200ml C/RECRAVE SOROPACK | E17: =E18 -> 4608
A18: EMMRST03 | B18: SOBRETAMPA CILINDRICA RECRAVE NATURAL | E18: =E11 -> 4608
A26: EMMRCX03 | B26: CAIXA DE PAPELAO BODY SPLASH REFRESCANTE | E26: =E11/INDEX([1]Produtos!$M:$M,MATCH(B11,[1]Produtos!$C:$C,0)) -> 96
A27: - | B27: ETIQUETA PARA CAIXA DE EMBARQUE 90x55mm | E27: =E26 -> 96
A29: CONTROLE DE QUANTIDADE PRODUZIDA
A30: Pallet | B30: qtde (cx) | C30: qtde (Un.) | D30: Conferido estoque | E30: Observações:
A31: 1
A32: 2
A33: 3
A34: Subtotal:
A35: Total em peças:
A37: Entrada sistema em: ____/____/____ por:___________
A45: __________________________________________
A46: RESPONSÁVEL

Sheet OF
H1: OP:
D2: ORDEM DE FABRICAÇÃO | H2: ='OP 1'!F2 -> 26183/03
A5: PRODUTO: | C5: ='OP 1'!B11 -> BODY SPLASH AMBAR REAL 200ml | F5: LOTE | G5: =H2 -> 26183/03 | H5: ADICIONAL
A6: CLIENTE: | C6: ='OP 1'!B7 -> MISS RÔSE | F6: QNT | G6: ='OP 1'!E11*'OP 1'!F11*(1+H6) -> 990.72 | H6: 0
A7: ='OP 1'!A7 -> 46205 | C7: ='OP 1'!A11 -> MRARBS10 | F7: BATELADA | G7: 1
A8: MANIPULADO POR:
A9: INICIO:___/____/___ - ___:___
A10: TERMINO:___/____/___ - ___:___
A13: LOTE | B13: SKU | C13: MATÉRIA-PRIMA | E13: % | F13: QT | G13: DENSIDADE | H13: VOLUME | I13: MANIP. | J13: PESO/VOL. REAL
C14: FASE A
B15: MPGR001 | C15: AGUA | E15: =100-SUM(E16:E26) -> 26.771 | F15: =(E15*$G$6)/100*G15 -> 265.22565 | G15: 1 | H15: =F15/G15 -> 265.22565
C16: ÁLCOOL 96° | E16: 70.389 | F16: =(E16*$G$6)/100*G16 -> 557.88632 | G16: 0.8 | H16: =F16/G16 -> 697.3579
B17: MPES124 | C17: ESSÊNCIA REF: GF48426/ROYALTY mod 3 | E17: 2.8 | F17: =(E17*$G$6)/100*G17 -> 27.74016 | G17: 1 | H17: =F17/G17 -> 27.74016
C18: METILISOTIAZOLINONA | E18: 0.04 | F18: =(E18*$G$6)/100*G18 -> 0.396288 | G18: 1 | H18: =F18/G18 -> 0.396288
C33: TOTAL | E33: =SUM(E15:E32) -> 100 | F33: =SUM(F15:F32) -> 851.24842 | G33: - | H33: =SUM(H15:H32) -> 990.72 | I33: =SUM(I15:I32) -> 0
A35: INSTRUÇÃO
A43: OCORRÊNCIA:____________________________________________________________ | F43: Analise de Processo
A44: ________________________________________________________________________ | F44: TESTE | G44: ESPECIFICAÇÃO | H44: RESULTADO
A45: ________________________________________________________________________ | F45: ASPECTO | G45: ='RELATÓRIO PRODUTO ACABADO'!D16 -> Líquido
A46: ________________________________________________________________________ | F46: COR | G46: ='RELATÓRIO PRODUTO ACABADO'!D17 -> Transparente
F47: ODOR | G47: ='RELATÓRIO PRODUTO ACABADO'!D19 -> 170g - 190g
A48: ________________________________________________________________________ | F48: DENSIDADE | G48: ='RELATÓRIO PRODUTO ACABADO'!D18 -> 0,8 - 0,9
A49: ________________________________________________________________________ | F49: TEOR DE ALCOOL | G49: ='RELATÓRIO PRODUTO ACABADO'!D21 -> 65°g/L - 75°g/L
A50: ________________________________________________________________________ | F50: pH | G50: ='RELATÓRIO PRODUTO ACABADO'!D27 -> NA
A56: APROVADO POR | D56: DATA____/_____/____

Sheet ORDEM DE ENVASE
J1: OP:
C2: ORDEM DE ENVASE | J2: ='OP 1'!F2 -> 26183/03
J3: EMISSÃO: | K3: ='OP 1'!A7 -> 46205
A5: PRODUTO: | B5: ='OP 1'!B11 -> BODY SPLASH AMBAR REAL 200ml | F5: ='OP 1'!A11 -> MRARBS10 | H5: QNT.: | I5: ='OP 1'!E11 -> 4608 | J5: ="Volume = "&'OP 1'!F11 -> Volume = 0,215 | K5: ="Densi. = "&'OP 1'!G11 -> Densi. = 1
A6: MS | H6: QNT.: | I6: ='OP 1'!E26 -> 96
A7: VALIDADE: | B7: =K3+1096 -> 47301 | H7: LOTE | I7: ='OP 1'!F2 -> 26183/03
A8: CÓDIGO DO CLIENTE: | B8: ='OP 1'!A12 -> MR157/E
A9: OPERADOR:
A10: LINHA DE PRODUÇÃO:
A11: MÁQUINA:
A12: INíCIO DE SETUP: | B12: ___/____/___ - ___:___ | C12: TÉRMINO DE SETUP: | D12: ___/____/___ - ___:___
A13: INÍCIO DE ENVASE: | B13: ___/____/___ - ___:___ | C13: TÉRMINO DE ENVASE: | D13: ___/____/___ - ___:___
A16: SKU | B16: INSUMOS | F16: Quantidade | H16: QUANT. PADRÃO | I16: QUANT. REAL | J16: AVARIA | K16: CONFERIDO
B17: =IF('OP 1'!B15=0,"",'OP 1'!B15) -> FORMULA BODY SPLASH AMBAR REAL 200ml | F17: =IF('OP 1'!E15=0,"",'OP 1'!E15) -> 990.72
B18: =IF('OP 1'!B16=0,"",'OP 1'!B16) -> ROTULO BODY SPLASH AMBAR REAL - (MISS ROSE) | F18: =IF('OP 1'!E16=0,"",'OP 1'!E16) -> 4608
B19: =IF('OP 1'!B16=0,"",'OP 1'!B16) -> ROTULO BODY SPLASH AMBAR REAL - (MISS ROSE) | F19: =IF('OP 1'!E17=0,"",'OP 1'!E17) -> 4608
B20: =IF('OP 1'!B18=0,"",'OP 1'!B18) -> SOBRETAMPA CILINDRICA RECRAVE NATURAL | F20: =IF('OP 1'!E18=0,"",'OP 1'!E18) -> 4608
B21: =IF('OP 1'!B19=0,"",'OP 1'!B19) | F21: =IF('OP 1'!E19=0,"",'OP 1'!E19)
B22: =IF('OP 1'!B26=0,"",'OP 1'!B26) -> CAIXA DE PAPELAO BODY SPLASH REFRESCANTE | F22: =IF('OP 1'!E26=0,"",'OP 1'!E26) -> 96
B23: =IF('OP 1'!B27=0,"",'OP 1'!B27) -> ETIQUETA PARA CAIXA DE EMBARQUE 90x55mm | F23: =IF('OP 1'!E27=0,"",'OP 1'!E27) -> 96
B24: BOMBA DE FILTRAÇÃO | F24: 1 UN
B27: =IF('OP 1'!B24=0,"",'OP 1'!B24) | F27: =IF('OP 1'!E24=0,"",'OP 1'!E24)
A29: EQUIPE 1
A30: Operação | C30: Responsável | F30: Data | I30: Hora
A31: VÁLVULA | F31: __/__/__ | I31: I:
I32: F:
A33: FRASCO | F33: __/__/__ | I33: I:
I34: F:
A35: TAMPA | F35: __/__/__ | I35: I:
I36: F:
A37: LACRE | F37: __/__/__ | I37: I:
I38: F:
A39: CAIXA | F39: __/__/__ | I39: I:
I40: F:
A41: PARADAS POR TURNO
A42: Motivo | E42: Início | F42: Final | G42: Turno | I42: Responsável
E43: : | F43: :
E44: : | F44: :
E45: : | F45: :
E46: : | F46: :
...

Sheet ROTULAGEM
A1: ,
B2: ORDEM DE ROTULAGEM | F2: ='OP 1'!A7 -> 46205
A4: CLIENTE | B4: SKU | C4: DESCRIÇÃO ITEM | F4: OP:
A5: ='OP 1'!B7 -> MISS RÔSE | B5: ='OP 1'!A11 -> MRARBS10 | C5: ='OP 1'!B11 -> BODY SPLASH AMBAR REAL 200ml | F5: ='OP 1'!F2 -> 26183/03
A7: Máquina
A8: Descrição do Material | E8: Unidade | F8: Qtde
A9: ='OP 1'!B11 -> BODY SPLASH AMBAR REAL 200ml | E9: PÇ | F9: ='OP 1'!E11 -> 4608
A10: APONTAMENTOS DA ORDEM DE PRODUÇÃO
A11: INÍCIO (data e hora) | B11: TÉRMINO (data e hora) | E11: QUANTIDADE
A13: ___/____/___ - _____:_____ | B13: ___/____/___ - _____:_____
A15: PARADAS POR TURNO
A16: Motivo | B16: INICIO | C16: Final | D16: Turno | E16: Responsável
A21: APONTAMENTOS DE PERDAS
A22: CÓDIGO | B22: DESCRIÇÃO | F22: QTDE | G22: LOTE
A29: OBSERVAÇÃO:

Sheet RELATÓRIO PRODUTO ACABADO
D3: Laboratório de Controle de Qualidade
D5: Relatório de Produto Acabado
B7: Cliente: | C7: ='OP 1'!B7 -> MISS RÔSE
B8: Produto: | C8: ='OP 1'!B11 -> BODY SPLASH AMBAR REAL 200ml
B9: Lote: | C9: ='OP 1'!F2 -> 26183/03
B10: Data de Fabricação: | C10: ___/____/___
B11: Validade: | C11: ='ORDEM DE ENVASE'!B7 -> 47301
B12: Quantidade de itens: | C12: ='OP 1'!E11 -> 4608
B13: Quantidade Requerida: | C13: ='OP 1'!E26 -> 96
B14: Análise Produto Fabricado
B15: TESTE | D15: ESPECIFICAÇÃO | G15: RESULTADO | I15: PA
B16: Aspecto | D16: Líquido | I16: PA 09
B17: Cor | D17: Transparente | G17: - | I17: PA 09
B18: Densidade | D18: 0,8 - 0,9 | I18: PA 03
B19: Odor | D19: 170g - 190g | I19: PA 09
B20: Ph | D20: NA | I20: PA 01
B21: TEOR DE ALCOOL | D21: 65°g/L - 75°g/L | I21: PA 08
B22: Análise Produto Envasado
B23: Aspecto | D23: =D16 -> Líquido | I23: PA 09
B24: Cor | D24: =D17 -> Transparente | I24: PA09
B25: Conteúdo Líquido Médio | D25: 170g - 190g | I25: PA03
B26: Odor | D26: Caracteristico | I26: PA09
B27: Ph | D27: =D20 -> NA | I27: PA01
B30: APROVADO REPROVADO RESPONSÁVEL
B32: Produto Envasado
B36: APROVADO REPROVADO RESPONSÁVEL

Sheet BUSCA LOTE
C2: 1 | D2: 2 | E2: =D2+1 -> 3 | F2: =E2+1 -> 4 | G2: =F2+1 -> 5 | H2: =G2+1 -> 6 | I2: =H2+1 -> 7 | J2: =I2+1 -> 8 | K2: =J2+1 -> 9 | L2: =K2+1 -> 10 | ... N2: =M2+1 -> 12
B3: 1 | C3: 1 | D3: =C33+1 -> 32 | E3: =D30+1 -> 60 | F3: =E33+1 -> 91 | G3: =F32+1 -> 121 | H3: =G33+1 -> 152 | I3: =H32+1 -> 182 | J3: =I33+1 -> 213 | K3: =J33+1 -> 244 | L3: =K32+1 -> 274 | M3: =L33+1 -> 305 | N3: =M32+1 -> 335
B4: =B3+1 -> 2 | C4: =C3+1 -> 2 | D4: =D3+1 -> 33 | E4: =E3+1 -> 61 | F4: =F3+1 -> 92 | G4: =G3+1 -> 122 | H4: =H3+1 -> 153 | I4: =I3+1 -> 183 | ... N4: =N3+1 -> 336
B5: =B4+1 -> 3 | C5: =C4+1 -> 3 | D5: =D4+1 -> 34 | E5: =E4+1 -> 62 | F5: =F4+1 -> 93 | G5: =G4+1 -> 123 | H5: =H4+1 -> 154 | I5: =I4+1 -> 184 | ... N5: =N4+1 -> 337
B6: =B5+1 -> 4 | C6: =C5+1 -> 4 | D6: =D5+1 -> 35 | E6: =E5+1 -> 63 | F6: =F5+1 -> 94 | G6: =G5+1 -> 124 | H6: =H5+1 -> 155 | I6: =I5+1 -> 185 | ... N6: =N5+1 -> 338
B7: =B6+1 -> 5 | C7: =C6+1 -> 5 | D7: =D6+1 -> 36 | E7: =E6+1 -> 64 | F7: =F6+1 -> 95 | G7: =G6+1 -> 125 | H7: =H6+1 -> 156 | I7: =I6+1 -> 186 | ... N7: =N6+1 -> 339
B8: =B7+1 -> 6 | C8: =C7+1 -> 6 | D8: =D7+1 -> 37 | E8: =E7+1 -> 65 | F8: =F7+1 -> 96 | G8: =G7+1 -> 126 | H8: =H7+1 -> 157 | I8: =I7+1 -> 187 | ... N8: =N7+1 -> 340 | Q8: 46205
B9: =B8+1 -> 7 | C9: =C8+1 -> 7 | D9: =D8+1 -> 38 | E9: =E8+1 -> 66 | F9: =F8+1 -> 97 | G9: =G8+1 -> 127 | H9: =H8+1 -> 158 | I9: =I8+1 -> 188 | ... N9: =N8+1 -> 341 | Q9: =RIGHT(YEAR(Q8),2)&INDEX($C$3:$N$33,MATCH(DAY(Q8),$B$3:$B$33,0),MATCH(MONTH($Q$8),$C$2:$N$2,0)) -> 26183
B10: =B9+1 -> 8 | C10: =C9+1 -> 8 | D10: =D9+1 -> 39 | E10: =E9+1 -> 67 | F10: =F9+1 -> 98 | G10: =G9+1 -> 128 | H10: =H9+1 -> 159 | I10: =I9+1 -> 189 | ... N10: =N9+1 -> 342
B11: =B10+1 -> 9 | C11: =C10+1 -> 9 | D11: =D10+1 -> 40 | E11: =E10+1 -> 68 | F11: =F10+1 -> 99 | G11: =G10+1 -> 129 | H11: =H10+1 -> 160 | I11: =I10+1 -> 190 | ... N11: =N10+1 -> 343
B12: =B11+1 -> 10 | C12: =C11+1 -> 10 | D12: =D11+1 -> 41 | E12: =E11+1 -> 69 | F12: =F11+1 -> 100 | G12: =G11+1 -> 130 | H12: =H11+1 -> 161 | I12: =I11+1 -> 191 | ... N12: =N11+1 -> 344
B13: =B12+1 -> 11 | C13: =C12+1 -> 11 | D13: =D12+1 -> 42 | E13: =E12+1 -> 70 | F13: =F12+1 -> 101 | G13: =G12+1 -> 131 | H13: =H12+1 -> 162 | I13: =I12+1 -> 192 | ... N13: =N12+1 -> 345
B14: =B13+1 -> 12 | C14: =C13+1 -> 12 | D14: =D13+1 -> 43 | E14: =E13+1 -> 71 | F14: =F13+1 -> 102 | G14: =G13+1 -> 132 | H14: =H13+1 -> 163 | I14: =I13+1 -> 193 | ... N14: =N13+1 -> 346
B15: =B14+1 -> 13 | C15: =C14+1 -> 13 | D15: =D14+1 -> 44 | E15: =E14+1 -> 72 | F15: =F14+1 -> 103 | G15: =G14+1 -> 133 | H15: =H14+1 -> 164 | I15: =I14+1 -> 194 | ... N15: =N14+1 -> 347
B16: =B15+1 -> 14 | C16: =C15+1 -> 14 | D16: =D15+1 -> 45 | E16: =E15+1 -> 73 | F16: =F15+1 -> 104 | G16: =G15+1 -> 134 | H16: =H15+1 -> 165 | I16: =I15+1 -> 195 | ... N16: =N15+1 -> 348
B17: =B16+1 -> 15 | C17: =C16+1 -> 15 | D17: =D16+1 -> 46 | E17: =E16+1 -> 74 | F17: =F16+1 -> 105 | G17: =G16+1 -> 135 | H17: =H16+1 -> 166 | I17: =I16+1 -> 196 | ... N17: =N16+1 -> 349
B18: =B17+1 -> 16 | C18: =C17+1 -> 16 | D18: =D17+1 -> 47 | E18: =E17+1 -> 75 | F18: =F17+1 -> 106 | G18: =G17+1 -> 136 | H18: =H17+1 -> 167 | I18: =I17+1 -> 197 | ... N18: =N17+1 -> 350
B19: =B18+1 -> 17 | C19: =C18+1 -> 17 | D19: =D18+1 -> 48 | E19: =E18+1 -> 76 | F19: =F18+1 -> 107 | G19: =G18+1 -> 137 | H19: =H18+1 -> 168 | I19: =I18+1 -> 198 | ... N19: =N18+1 -> 351
B20: =B19+1 -> 18 | C20: =C19+1 -> 18 | D20: =D19+1 -> 49 | E20: =E19+1 -> 77 | F20: =F19+1 -> 108 | G20: =G19+1 -> 138 | H20: =H19+1 -> 169 | I20: =I19+1 -> 199 | ... N20: =N19+1 -> 352
B21: =B20+1 -> 19 | C21: =C20+1 -> 19 | D21: =D20+1 -> 50 | E21: =E20+1 -> 78 | F21: =F20+1 -> 109 | G21: =G20+1 -> 139 | H21: =H20+1 -> 170 | I21: =I20+1 -> 200 | ... N21: =N20+1 -> 353
... B30: =B29+1 -> 28 | C30: =C29+1 -> 28 | D30: =D29+1 -> 59 | E30: =E29+1 -> 87 | F30: =F29+1 -> 118 | G30: =G29+1 -> 148 | H30: =H29+1 -> 179 | I30: =I29+1 -> 209 | ... N30: =N29+1 -> 362
B31: =B30+1 -> 29 | C31: =C30+1 -> 29 | E31: =E30+1 -> 88 | F31: =F30+1 -> 119 | G31: =G30+1 -> 149 | H31: =H30+1 -> 180 | I31: =I30+1 -> 210 | J31: =J30+1 -> 241 | K31: =K30+1 -> 272 | L31: =L30+1 -> 302 | ... N31: =N30+1 -> 363
B32: =B31+1 -> 30 | C32: =C31+1 -> 30 | E32: =E31+1 -> 89 | F32: =F31+1 -> 120 | G32: =G31+1 -> 150 | H32: =H31+1 -> 181 | I32: =I31+1 -> 211 | J32: =J31+1 -> 242 | K32: =K31+1 -> 273 | L32: =L31+1 -> 303 | ... N32: =N31+1 -> 364
B33: =B32+1 -> 31 | C33: =C32+1 -> 31 | E33: =E32+1 -> 90 | G33: =G32+1 -> 151 | I33: =I32+1 -> 212 | J33: =J32+1 -> 243 | L33: =L32+1 -> 304 | N33: =N32+1 -> 365
