Workbook

Sheet Gerador de SKU
A1: GERADOR DE SKU
A2: ENTRADA (preencher) | F2: CALCULO (automatico) | L2: REGISTRO
A3: Nome do Produto | B3: Cliente | C3: Volume | D3: Unidade | E3: Forma Manual (CAT3) | F3: CAT3 Sugerido | G3: Qtd Formas Encontradas | H3: Confianca | I3: CLI4 | J3: SEQ4 | K3: SKU Final | L3: Volume/Apresentacao | M3: _NomeNorm | N3: _CAT3Auto
F4: =IF($A4="","",IF($E4<>"",UPPER($E4),$N4)) | G4: {=IF($M4="","",SUM(_xlfn.BYROW(tblFormas[PalavrasChave],_xlfn.LAMBDA(_xlpm.k,IF(_xlpm.k="",0,--OR(ISNUMBER(SEARCH(_xlfn.TEXTSPLIT(_xlpm.k,";"),$M4))))))))} | H4: =IF($A4="","",IF($E4<>"","ALTA",IF($G4=1,"ALTA",IF($G4>=2,"REVISAR - MULTIPLAS","REVISAR - NENHUMA")))) | I4: =IF($B4="","",_xlfn.LET(_xlpm.v,IFERROR(_xlfn.XLOOKUP($B4,tblClientes[Cliente],tblClientes[CLI4],""),""),IF(_xlpm.v=0,"",_xlpm.v))) | J4: =IF(OR($F4="",$I4=""),"",TEXT(COUNTIF(Produtos!$B:$B,$F4&"-"&$I4&"-*")+COUNTIFS($F$3:F3,$F4,$I$3:I3,$I4)+1,"0000")) | K4: =IF($A4="","",IF($I4="","CLIENTE SEM CLI4",IF($H4="ALTA",$F4&"-"&$I4&"-"&$J4,$H4))) | L4: =IF($C4="","",TRIM($C4&" "&$D4)) | M4: =IF($A4="","",SUBSTITUTE(SUBSTITUTE(SUBSTITUTE(SUBSTITUTE(SUBSTITUTE(SUBSTITUTE(SUBSTITUTE(SUBSTITUTE(SUBSTITUTE(SUBSTITUTE(SUBSTITUTE(SUBSTITUTE(SUBSTITUTE(SUBSTITUTE(SUBSTITUTE(SUBSTITUTE(SUBSTITUTE(LOWER($A4),"á","a"),"à","a"),"â","a"),"ã","a"),"ä","a"),"é","e"),"ê","e"),"è","e"),"í","i"),"ï","i"),"ó","o"),"ô","o"),"õ","o"),"ò","o"),"ú","u"),"ü","u"),"ç","c")) | N4: {=IF($M4="","",IFERROR(INDEX(tblFormas[CAT3],MATCH(TRUE,_xlfn.BYROW(tblFormas[PalavrasChave],_xlfn.LAMBDA(_xlpm.k,IF(_xlpm.k="",FALSE,OR(ISNUMBER(SEARCH(_xlfn.TEXTSPLIT(_xlpm.k,";"),$M4)))))),0)),""))}
F5: =IF($A5="","",IF($E5<>"",UPPER($E5),$N5)) | G5: {=IF($M5="","",SUM(_xlfn.BYROW(tblFormas[PalavrasChave],_xlfn.LAMBDA(_xlpm.k,IF(_xlpm.k="",0,--OR(ISNUMBER(SEARCH(_xlfn.TEXTSPLIT(_xlpm.k,";"),$M5))))))))} | H5: =IF($A5="","",IF($E5<>"","ALTA",IF($G5=1,"ALTA",IF($G5>=2,"REVISAR - MULTIPLAS","REVISAR - NENHUMA")))) | I5: =IF($B5="","",_xlfn.LET(_xlpm.v,IFERROR(_xlfn.XLOOKUP($B5,tblClientes[Cliente],tblClientes[CLI4],""),""),IF(_xlpm.v=0,"",_xlpm.v))) | J5: =IF(OR($F5="",$I5=""),"",TEXT(COUNTIF(Produtos!$B:$B,$F5&"-"&$I5&"-*")+COUNTIFS($F$3:F4,$F5,$I$3:I4,$I5)+1,"0000")) | K5: =IF($A5="","",IF($I5="","CLIENTE SEM CLI4",IF($H5="ALTA",$F5&"-"&$I5&"-"&$J5,$H5))) | L5: =IF($C5="","",TRIM($C5&" "&$D5)) | M5: =IF($A5="","",SUBSTITUTE(SUBSTITUTE(SUBSTITUTE(SUBSTITUTE(SUBSTITUTE(SUBSTITUTE(SUBSTITUTE(SUBSTITUTE(SUBSTITUTE(SUBSTITUTE(SUBSTITUTE(SUBSTITUTE(SUBSTITUTE(SUBSTITUTE(SUBSTITUTE(SUBSTITUTE(SUBSTITUTE(LOWER($A5),"á","a"),"à","a"),"â","a"),"ã","a"),"ä","a"),"é","e"),"ê","e"),"è","e"),"í","i"),"ï","i"),"ó","o"),"ô","o"),"õ","o"),"ò","o"),"ú","u"),"ü","u"),"ç","c")) | N5: {=IF($M5="","",IFERROR(INDEX(tblFormas[CAT3],MATCH(TRUE,_xlfn.BYROW(tblFormas[PalavrasChave],_xlfn.LAMBDA(_xlpm.k,IF(_xlpm.k="",FALSE,OR(ISNUMBER(SEARCH(_xlfn.TEXTSPLIT(_xlpm.k,";"),$M5)))))),0)),""))}
F6: =IF($A6="","",IF($E6<>"",UPPER($E6),$N6)) | G6: {=IF($M6="","",SUM(_xlfn.BYROW(tblFormas[PalavrasChave],_xlfn.LAMBDA(_xlpm.k,IF(_xlpm.k="",0,--OR(ISNUMBER(SEARCH(_xlfn.TEXTSPLIT(_xlpm.k,";"),$M6))))))))} | H6: =IF($A6="","",IF($E6<>"","ALTA",IF($G6=1,"ALTA",IF($G6>=2,"REVISAR - MULTIPLAS","REVISAR - NENHUMA")))) | I6: =IF($B6="","",_xlfn.LET(_xlpm.v,IFERROR(_xlfn.XLOOKUP($B6,tblClientes[Cliente],tblClientes[CLI4],""),""),IF(_xlpm.v=0,"",_xlpm.v))) | J6: =IF(OR($F6="",$I6=""),"",TEXT(COUNTIF(Produtos!$B:$B,$F6&"-"&$I6&"-*")+COUNTIFS($F$3:F5,$F6,$I$3:I5,$I6)+1,"0000")) | K6: =IF($A6="","",IF($I6="","CLIENTE SEM CLI4",IF($H6="ALTA",$F6&"-"&$I6&"-"&$J6,$H6))) | L6: =IF($C6="","",TRIM($C6&" "&$D6)) | M6: =IF($A6="","",SUBSTITUTE(SUBSTITUTE(SUBSTITUTE(SUBSTITUTE(SUBSTITUTE(SUBSTITUTE(SUBSTITUTE(SUBSTITUTE(SUBSTITUTE(SUBSTITUTE(SUBSTITUTE(SUBSTITUTE(SUBSTITUTE(SUBSTITUTE(SUBSTITUTE(SUBSTITUTE(SUBSTITUTE(LOWER($A6),"á","a"),"à","a"),"â","a"),"ã","a"),"ä","a"),"é","e"),"ê","e"),"è","e"),"í","i"),"ï","i"),"ó","o"),"ô","o"),"õ","o"),"ò","o"),"ú","u"),"ü","u"),"ç","c")) | N6: {=IF($M6="","",IFERROR(INDEX(tblFormas[CAT3],MATCH(TRUE,_xlfn.BYROW(tblFormas[PalavrasChave],_xlfn.LAMBDA(_xlpm.k,IF(_xlpm.k="",FALSE,OR(ISNUMBER(SEARCH(_xlfn.TEXTSPLIT(_xlpm.k,";"),$M6)))))),0)),""))}
F7: =IF($A7="","",IF($E7<>"",UPPER($E7),$N7)) | G7: {=IF($M7="","",SUM(_xlfn.BYROW(tblFormas[PalavrasChave],_xlfn.LAMBDA(_xlpm.k,IF(_xlpm.k="",0,--OR(ISNUMBER(SEARCH(_xlfn.TEXTSPLIT(_xlpm.k,";"),$M7))))))))} | H7: =IF($A7="","",IF($E7<>"","ALTA",IF($G7=1,"ALTA",IF($G7>=2,"REVISAR - MULTIPLAS","REVISAR - NENHUMA")))) | I7: =IF($B7="","",_xlfn.LET(_xlpm.v,IFERROR(_xlfn.XLOOKUP($B7,tblClientes[Cliente],tblClientes[CLI4],""),""),IF(_xlpm.v=0,"",_xlpm.v))) | J7: =IF(OR($F7="",$I7=""),"",TEXT(COUNTIF(Produtos!$B:$B,$F7&"-"&$I7&"-*")+COUNTIFS($F$3:F6,$F7,$I$3:I6,$I7)+1,"0000")) | K7: =IF($A7="","",IF($I7="","CLIENTE SEM CLI4",IF($H7="ALTA",$F7&"-"&$I7&"-"&$J7,$H7))) | L7: =IF($C7="","",TRIM($C7&" "&$D7)) | M7: =IF($A7="","",SUBSTITUTE(SUBSTITUTE(SUBSTITUTE(SUBSTITUTE(SUBSTITUTE(SUBSTITUTE(SUBSTITUTE(SUBSTITUTE(SUBSTITUTE(SUBSTITUTE(SUBSTITUTE(SUBSTITUTE(SUBSTITUTE(SUBSTITUTE(SUBSTITUTE(SUBSTITUTE(SUBSTITUTE(LOWER($A7),"á","a"),"à","a"),"â","a"),"ã","a"),"ä","a"),"é","e"),"ê","e"),"è","e"),"í","i"),"ï","i"),"ó","o"),"ô","o"),"õ","o"),"ò","o"),"ú","u"),"ü","u"),"ç","c")) | N7: {=IF($M7="","",IFERROR(INDEX(tblFormas[CAT3],MATCH(TRUE,_xlfn.BYROW(tblFormas[PalavrasChave],_xlfn.LAMBDA(_xlpm.k,IF(_xlpm.k="",FALSE,OR(ISNUMBER(SEARCH(_xlfn.TEXTSPLIT(_xlpm.k,";"),$M7)))))),0)),""))}
F8: =IF($A8="","",IF($E8<>"",UPPER($E8),$N8)) | G8: {=IF($M8="","",SUM(_xlfn.BYROW(tblFormas[PalavrasChave],_xlfn.LAMBDA(_xlpm.k,IF(_xlpm.k="",0,--OR(ISNUMBER(SEARCH(_xlfn.TEXTSPLIT(_xlpm.k,";"),$M8))))))))} | H8: =IF($A8="","",IF($E8<>"","ALTA",IF($G8=1,"ALTA",IF($G8>=2,"REVISAR - MULTIPLAS","REVISAR - NENHUMA")))) | I8: =IF($B8="","",_xlfn.LET(_xlpm.v,IFERROR(_xlfn.XLOOKUP($B8,tblClientes[Cliente],tblClientes[CLI4],""),""),IF(_xlpm.v=0,"",_xlpm.v))) | J8: =IF(OR($F8="",$I8=""),"",TEXT(COUNTIF(Produtos!$B:$B,$F8&"-"&$I8&"-*")+COUNTIFS($F$3:F7,$F8,$I$3:I7,$I8)+1,"0000")) | K8: =IF($A8="","",IF($I8="","CLIENTE SEM CLI4",IF($H8="ALTA",$F8&"-"&$I8&"-"&$J8,$H8))) | L8: =IF($C8="","",TRIM($C8&" "&$D8)) | M8: =IF($A8="","",SUBSTITUTE(SUBSTITUTE(SUBSTITUTE(SUBSTITUTE(SUBSTITUTE(SUBSTITUTE(SUBSTITUTE(SUBSTITUTE(SUBSTITUTE(SUBSTITUTE(SUBSTITUTE(SUBSTITUTE(SUBSTITUTE(SUBSTITUTE(SUBSTITUTE(SUBSTITUTE(SUBSTITUTE(LOWER($A8),"á","a"),"à","a"),"â","a"),"ã","a"),"ä","a"),"é","e"),"ê","e"),"è","e"),"í","i"),"ï","i"),"ó","o"),"ô","o"),"õ","o"),"ò","o"),"ú","u"),"ü","u"),"ç","c")) | N8: {=IF($M8="","",IFERROR(INDEX(tblFormas[CAT3],MATCH(TRUE,_xlfn.BYROW(tblFormas[PalavrasChave],_xlfn.LAMBDA(_xlpm.k,IF(_xlpm.k="",FALSE,OR(ISNUMBER(SEARCH(_xlfn.TEXTSPLIT(_xlpm.k,";"),$M8)))))),0)),""))}
F9: =IF($A9="","",IF($E9<>"",UPPER($E9),$N9)) | G9: {=IF($M9="","",SUM(_xlfn.BYROW(tblFormas[PalavrasChave],_xlfn.LAMBDA(_xlpm.k,IF(_xlpm.k="",0,--OR(ISNUMBER(SEARCH(_xlfn.TEXTSPLIT(_xlpm.k,";"),$M9))))))))} | H9: =IF($A9="","",IF($E9<>"","ALTA",IF($G9=1,"ALTA",IF($G9>=2,"REVISAR - MULTIPLAS","REVISAR - NENHUMA")))) | I9: =IF($B9="","",_xlfn.LET(_xlpm.v,IFERROR(_xlfn.XLOOKUP($B9,tblClientes[Cliente],tblClientes[CLI4],""),""),IF(_xlpm.v=0,"",_xlpm.v))) | J9: =IF(OR($F9="",$I9=""),"",TEXT(COUNTIF(Produtos!$B:$B,$F9&"-"&$I9&"-*")+COUNTIFS($F$3:F8,$F9,$I$3:I8,$I9)+1,"0000")) | K9: =IF($A9="","",IF($I9="","CLIENTE SEM CLI4",IF($H9="ALTA",$F9&"-"&$I9&"-"&$J9,$H9))) | L9: =IF($C9="","",TRIM($C9&" "&$D9)) | M9: =IF($A9="","",SUBSTITUTE(SUBSTITUTE(SUBSTITUTE(SUBSTITUTE(SUBSTITUTE(SUBSTITUTE(SUBSTITUTE(SUBSTITUTE(SUBSTITUTE(SUBSTITUTE(SUBSTITUTE(SUBSTITUTE(SUBSTITUTE(SUBSTITUTE(SUBSTITUTE(SUBSTITUTE(SUBSTITUTE(LOWER($A9),"á","a"),"à","a"),"â","a"),"ã","a"),"ä","a"),"é","e"),"ê","e"),"è","e"),"í","i"),"ï","i"),"ó","o"),"ô","o"),"õ","o"),"ò","o"),"ú","u"),"ü","u"),"ç","c")) | N9: {=IF($M9="","",IFERROR(INDEX(tblFormas[CAT3],MATCH(TRUE,_xlfn.BYROW(tblFormas[PalavrasChave],_xlfn.LAMBDA(_xlpm.k,IF(_xlpm.k="",FALSE,OR(ISNUMBER(SEARCH(_xlfn.TEXTSPLIT(_xlpm.k,";"),$M9)))))),0)),""))}
F10: =IF($A10="","",IF($E10<>"",UPPER($E10),$N10)) | G10: {=IF($M10="","",SUM(_xlfn.BYROW(tblFormas[PalavrasChave],_xlfn.LAMBDA(_xlpm.k,IF(_xlpm.k="",0,--OR(ISNUMBER(SEARCH(_xlfn.TEXTSPLIT(_xlpm.k,";"),$M10))))))))} | H10: =IF($A10="","",IF($E10<>"","ALTA",IF($G10=1,"ALTA",IF($G10>=2,"REVISAR - MULTIPLAS","REVISAR - NENHUMA")))) | I10: =IF($B10="","",_xlfn.LET(_xlpm.v,IFERROR(_xlfn.XLOOKUP($B10,tblClientes[Cliente],tblClientes[CLI4],""),""),IF(_xlpm.v=0,"",_xlpm.v))) | J10: =IF(OR($F10="",$I10=""),"",TEXT(COUNTIF(Produtos!$B:$B,$F10&"-"&$I10&"-*")+COUNTIFS($F$3:F9,$F10,$I$3:I9,$I10)+1,"0000")) | K10: =IF($A10="","",IF($I10="","CLIENTE SEM CLI4",IF($H10="ALTA",$F10&"-"&$I10&"-"&$J10,$H10))) | L10: =IF($C10="","",TRIM($C10&" "&$D10)) | M10: =IF($A10="","",SUBSTITUTE(SUBSTITUTE(SUBSTITUTE(SUBSTITUTE(SUBSTITUTE(SUBSTITUTE(SUBSTITUTE(SUBSTITUTE(SUBSTITUTE(SUBSTITUTE(SUBSTITUTE(SUBSTITUTE(SUBSTITUTE(SUBSTITUTE(SUBSTITUTE(SUBSTITUTE(SUBSTITUTE(LOWER($A10),"á","a"),"à","a"),"â","a"),"ã","a"),"ä","a"),"é","e"),"ê","e"),"è","e"),"í","i"),"ï","i"),"ó","o"),"ô","o"),"õ","o"),"ò","o"),"ú","u"),"ü","u"),"ç","c")) | N10: {=IF($M10="","",IFERROR(INDEX(tblFormas[CAT3],MATCH(TRUE,_xlfn.BYROW(tblFormas[PalavrasChave],_xlfn.LAMBDA(_xlpm.k,IF(_xlpm.k="",FALSE,OR(ISNUMBER(SEARCH(_xlfn.TEXTSPLIT(_xlpm.k,";"),$M10)))))),0)),""))}
F11: =IF($A11="","",IF($E11<>"",UPPER($E11),$N11)) | G11: {=IF($M11="","",SUM(_xlfn.BYROW(tblFormas[PalavrasChave],_xlfn.LAMBDA(_xlpm.k,IF(_xlpm.k="",0,--OR(ISNUMBER(SEARCH(_xlfn.TEXTSPLIT(_xlpm.k,";"),$M11))))))))} | H11: =IF($A11="","",IF($E11<>"","ALTA",IF($G11=1,"ALTA",IF($G11>=2,"REVISAR - MULTIPLAS","REVISAR - NENHUMA")))) | I11: =IF($B11="","",_xlfn.LET(_xlpm.v,IFERROR(_xlfn.XLOOKUP($B11,tblClientes[Cliente],tblClientes[CLI4],""),""),IF(_xlpm.v=0,"",_xlpm.v))) | J11: =IF(OR($F11="",$I11=""),"",TEXT(COUNTIF(Produtos!$B:$B,$F11&"-"&$I11&"-*")+COUNTIFS($F$3:F10,$F11,$I$3:I10,$I11)+1,"0000")) | K11: =IF($A11="","",IF($I11="","CLIENTE SEM CLI4",IF($H11="ALTA",$F11&"-"&$I11&"-"&$J11,$H11))) | L11: =IF($C11="","",TRIM($C11&" "&$D11)) | M11: =IF($A11="","",SUBSTITUTE(SUBSTITUTE(SUBSTITUTE(SUBSTITUTE(SUBSTITUTE(SUBSTITUTE(SUBSTITUTE(SUBSTITUTE(SUBSTITUTE(SUBSTITUTE(SUBSTITUTE(SUBSTITUTE(SUBSTITUTE(SUBSTITUTE(SUBSTITUTE(SUBSTITUTE(SUBSTITUTE(LOWER($A11),"á","a"),"à","a"),"â","a"),"ã","a"),"ä","a"),"é","e"),"ê","e"),"è","e"),"í","i"),"ï","i"),"ó","o"),"ô","o"),"õ","o"),"ò","o"),"ú","u"),"ü","u"),"ç","c")) | N11: {=IF($M11="","",IFERROR(INDEX(tblFormas[CAT3],MATCH(TRUE,_xlfn.BYROW(tblFormas[PalavrasChave],_xlfn.LAMBDA(_xlpm.k,IF(_xlpm.k="",FALSE,OR(ISNUMBER(SEARCH(_xlfn.TEXTSPLIT(_xlpm.k,";"),$M11)))))),0)),""))}
F12: =IF($A12="","",IF($E12<>"",UPPER($E12),$N12)) | G12: {=IF($M12="","",SUM(_xlfn.BYROW(tblFormas[PalavrasChave],_xlfn.LAMBDA(_xlpm.k,IF(_xlpm.k="",0,--OR(ISNUMBER(SEARCH(_xlfn.TEXTSPLIT(_xlpm.k,";"),$M12))))))))} | H12: =IF($A12="","",IF($E12<>"","ALTA",IF($G12=1,"ALTA",IF($G12>=2,"REVISAR - MULTIPLAS","REVISAR - NENHUMA")))) | I12: =IF($B12="","",_xlfn.LET(_xlpm.v,IFERROR(_xlfn.XLOOKUP($B12,tblClientes[Cliente],tblClientes[CLI4],""),""),IF(_xlpm.v=0,"",_xlpm.v))) | J12: =IF(OR($F12="",$I12=""),"",TEXT(COUNTIF(Produtos!$B:$B,$F12&"-"&$I12&"-*")+COUNTIFS($F$3:F11,$F12,$I$3:I11,$I12)+1,"0000")) | K12: =IF($A12="","",IF($I12="","CLIENTE SEM CLI4",IF($H12="ALTA",$F12&"-"&$I12&"-"&$J12,$H12))) | L12: =IF($C12="","",TRIM($C12&" "&$D12)) | M12: =IF($A12="","",SUBSTITUTE(SUBSTITUTE(SUBSTITUTE(SUBSTITUTE(SUBSTITUTE(SUBSTITUTE(SUBSTITUTE(SUBSTITUTE(SUBSTITUTE(SUBSTITUTE(SUBSTITUTE(SUBSTITUTE(SUBSTITUTE(SUBSTITUTE(SUBSTITUTE(SUBSTITUTE(SUBSTITUTE(LOWER($A12),"á","a"),"à","a"),"â","a"),"ã","a"),"ä","a"),"é","e"),"ê","e"),"è","e"),"í","i"),"ï","i"),"ó","o"),"ô","o"),"õ","o"),"ò","o"),"ú","u"),"ü","u"),"ç","c")) | N12: {=IF($M12="","",IFERROR(INDEX(tblFormas[CAT3],MATCH(TRUE,_xlfn.BYROW(tblFormas[PalavrasChave],_xlfn.LAMBDA(_xlpm.k,IF(_xlpm.k="",FALSE,OR(ISNUMBER(SEARCH(_xlfn.TEXTSPLIT(_xlpm.k,";"),$M12)))))),0)),""))}
F13: =IF($A13="","",IF($E13<>"",UPPER($E13),$N13)) | G13: {=IF($M13="","",SUM(_xlfn.BYROW(tblFormas[PalavrasChave],_xlfn.LAMBDA(_xlpm.k,IF(_xlpm.k="",0,--OR(ISNUMBER(SEARCH(_xlfn.TEXTSPLIT(_xlpm.k,";"),$M13))))))))} | H13: =IF($A13="","",IF($E13<>"","ALTA",IF($G13=1,"ALTA",IF($G13>=2,"REVISAR - MULTIPLAS","REVISAR - NENHUMA")))) | I13: =IF($B13="","",_xlfn.LET(_xlpm.v,IFERROR(_xlfn.XLOOKUP($B13,tblClientes[Cliente],tblClientes[CLI4],""),""),IF(_xlpm.v=0,"",_xlpm.v))) | J13: =IF(OR($F13="",$I13=""),"",TEXT(COUNTIF(Produtos!$B:$B,$F13&"-"&$I13&"-*")+COUNTIFS($F$3:F12,$F13,$I$3:I12,$I13)+1,"0000")) | K13: =IF($A13="","",IF($I13="","CLIENTE SEM CLI4",IF($H13="ALTA",$F13&"-"&$I13&"-"&$J13,$H13))) | L13: =IF($C13="","",TRIM($C13&" "&$D13)) | M13: =IF($A13="","",SUBSTITUTE(SUBSTITUTE(SUBSTITUTE(SUBSTITUTE(SUBSTITUTE(SUBSTITUTE(SUBSTITUTE(SUBSTITUTE(SUBSTITUTE(SUBSTITUTE(SUBSTITUTE(SUBSTITUTE(SUBSTITUTE(SUBSTITUTE(SUBSTITUTE(SUBSTITUTE(SUBSTITUTE(LOWER($A13),"á","a"),"à","a"),"â","a"),"ã","a"),"ä","a"),"é","e"),"ê","e"),"è","e"),"í","i"),"ï","i"),"ó","o"),"ô","o"),"õ","o"),"ò","o"),"ú","u"),"ü","u"),"ç","c")) | N13: {=IF($M13="","",IFERROR(INDEX(tblFormas[CAT3],MATCH(TRUE,_xlfn.BYROW(tblFormas[PalavrasChave],_xlfn.LAMBDA(_xlpm.k,IF(_xlpm.k="",FALSE,OR(ISNUMBER(SEARCH(_xlfn.TEXTSPLIT(_xlpm.k,";"),$M13)))))),0)),""))}
F14: =IF($A14="","",IF($E14<>"",UPPER($E14),$N14)) | G14: {=IF($M14="","",SUM(_xlfn.BYROW(tblFormas[PalavrasChave],_xlfn.LAMBDA(_xlpm.k,IF(_xlpm.k="",0,--OR(ISNUMBER(SEARCH(_xlfn.TEXTSPLIT(_xlpm.k,";"),$M14))))))))} | H14: =IF($A14="","",IF($E14<>"","ALTA",IF($G14=1,"ALTA",IF($G14>=2,"REVISAR - MULTIPLAS","REVISAR - NENHUMA")))) | I14: =IF($B14="","",_xlfn.LET(_xlpm.v,IFERROR(_xlfn.XLOOKUP($B14,tblClientes[Cliente],tblClientes[CLI4],""),""),IF(_xlpm.v=0,"",_xlpm.v))) | J14: =IF(OR($F14="",$I14=""),"",TEXT(COUNTIF(Produtos!$B:$B,$F14&"-"&$I14&"-*")+COUNTIFS($F$3:F13,$F14,$I$3:I13,$I14)+1,"0000")) | K14: =IF($A14="","",IF($I14="","CLIENTE SEM CLI4",IF($H14="ALTA",$F14&"-"&$I14&"-"&$J14,$H14))) | L14: =IF($C14="","",TRIM($C14&" "&$D14)) | M14: =IF($A14="","",SUBSTITUTE(SUBSTITUTE(SUBSTITUTE(SUBSTITUTE(SUBSTITUTE(SUBSTITUTE(SUBSTITUTE(SUBSTITUTE(SUBSTITUTE(SUBSTITUTE(SUBSTITUTE(SUBSTITUTE(SUBSTITUTE(SUBSTITUTE(SUBSTITUTE(SUBSTITUTE(SUBSTITUTE(LOWER($A14),"á","a"),"à","a"),"â","a"),"ã","a"),"ä","a"),"é","e"),"ê","e"),"è","e"),"í","i"),"ï","i"),"ó","o"),"ô","o"),"õ","o"),"ò","o"),"ú","u"),"ü","u"),"ç","c")) | N14: {=IF($M14="","",IFERROR(INDEX(tblFormas[CAT3],MATCH(TRUE,_xlfn.BYROW(tblFormas[PalavrasChave],_xlfn.LAMBDA(_xlpm.k,IF(_xlpm.k="",FALSE,OR(ISNUMBER(SEARCH(_xlfn.TEXTSPLIT(_xlpm.k,";"),$M14)))))),0)),""))}
F15: =IF($A15="","",IF($E15<>"",UPPER($E15),$N15)) | G15: {=IF($M15="","",SUM(_xlfn.BYROW(tblFormas[PalavrasChave],_xlfn.LAMBDA(_xlpm.k,IF(_xlpm.k="",0,--OR(ISNUMBER(SEARCH(_xlfn.TEXTSPLIT(_xlpm.k,";"),$M15))))))))} | H15: =IF($A15="","",IF($E15<>"","ALTA",IF($G15=1,"ALTA",IF($G15>=2,"REVISAR - MULTIPLAS","REVISAR - NENHUMA")))) | I15: =IF($B15="","",_xlfn.LET(_xlpm.v,IFERROR(_xlfn.XLOOKUP($B15,tblClientes[Cliente],tblClientes[CLI4],""),""),IF(_xlpm.v=0,"",_xlpm.v))) | J15: =IF(OR($F15="",$I15=""),"",TEXT(COUNTIF(Produtos!$B:$B,$F15&"-"&$I15&"-*")+COUNTIFS($F$3:F14,$F15,$I$3:I14,$I15)+1,"0000")) | K15: =IF($A15="","",IF($I15="","CLIENTE SEM CLI4",IF($H15="ALTA",$F15&"-"&$I15&"-"&$J15,$H15))) | L15: =IF($C15="","",TRIM($C15&" "&$D15)) | M15: =IF($A15="","",SUBSTITUTE(SUBSTITUTE(SUBSTITUTE(SUBSTITUTE(SUBSTITUTE(SUBSTITUTE(SUBSTITUTE(SUBSTITUTE(SUBSTITUTE(SUBSTITUTE(SUBSTITUTE(SUBSTITUTE(SUBSTITUTE(SUBSTITUTE(SUBSTITUTE(SUBSTITUTE(SUBSTITUTE(LOWER($A15),"á","a"),"à","a"),"â","a"),"ã","a"),"ä","a"),"é","e"),"ê","e"),"è","e"),"í","i"),"ï","i"),"ó","o"),"ô","o"),"õ","o"),"ò","o"),"ú","u"),"ü","u"),"ç","c")) | N15: {=IF($M15="","",IFERROR(INDEX(tblFormas[CAT3],MATCH(TRUE,_xlfn.BYROW(tblFormas[PalavrasChave],_xlfn.LAMBDA(_xlpm.k,IF(_xlpm.k="",FALSE,OR(ISNUMBER(SEARCH(_xlfn.TEXTSPLIT(_xlpm.k,";"),$M15)))))),0)),""))}
... F103: =IF($A103="","",IF($E103<>"",UPPER($E103),$N103)) | G103: {=IF($M103="","",SUM(_xlfn.BYROW(tblFormas[PalavrasChave],_xlfn.LAMBDA(_xlpm.k,IF(_xlpm.k="",0,--OR(ISNUMBER(SEARCH(_xlfn.TEXTSPLIT(_xlpm.k,";"),$M103))))))))} | H103: =IF($A103="","",IF($E103<>"","ALTA",IF($G103=1,"ALTA",IF($G103>=2,"REVISAR - MULTIPLAS","REVISAR - NENHUMA")))) | I103: =IF($B103="","",_xlfn.LET(_xlpm.v,IFERROR(_xlfn.XLOOKUP($B103,tblClientes[Cliente],tblClientes[CLI4],""),""),IF(_xlpm.v=0,"",_xlpm.v))) | J103: =IF(OR($F103="",$I103=""),"",TEXT(COUNTIF(Produtos!$B:$B,$F103&"-"&$I103&"-*")+COUNTIFS($F$3:F102,$F103,$I$3:I102,$I103)+1,"0000")) | K103: =IF($A103="","",IF($I103="","CLIENTE SEM CLI4",IF($H103="ALTA",$F103&"-"&$I103&"-"&$J103,$H103))) | L103: =IF($C103="","",TRIM($C103&" "&$D103)) | M103: =IF($A103="","",SUBSTITUTE(SUBSTITUTE(SUBSTITUTE(SUBSTITUTE(SUBSTITUTE(SUBSTITUTE(SUBSTITUTE(SUBSTITUTE(SUBSTITUTE(SUBSTITUTE(SUBSTITUTE(SUBSTITUTE(SUBSTITUTE(SUBSTITUTE(SUBSTITUTE(SUBSTITUTE(SUBSTITUTE(LOWER($A103),"á","a"),"à","a"),"â","a"),"ã","a"),"ä","a"),"é","e"),"ê","e"),"è","e"),"í","i"),"ï","i"),"ó","o"),"ô","o"),"õ","o"),"ò","o"),"ú","u"),"ü","u"),"ç","c")) | N103: {=IF($M103="","",IFERROR(INDEX(tblFormas[CAT3],MATCH(TRUE,_xlfn.BYROW(tblFormas[PalavrasChave],_xlfn.LAMBDA(_xlpm.k,IF(_xlpm.k="",FALSE,OR(ISNUMBER(SEARCH(_xlfn.TEXTSPLIT(_xlpm.k,";"),$M103)))))),0)),""))}

Sheet Produtos
B2: SKU | C2: Descrição do Item | D2: Linha do Produto | G2: Cliente | H2: Categoria do Produto | I2: Sub. do Produto | J2: Viscosidade | K2: Prod. p/ Hora | L2: Prod. Viscosidade | M2: Un. / Cx | N2: Qtd. Lote Padrão | O2: COD. CLIENTE | P2: Cod. Barras EAN-13 | Q2: Cod. Barras DUM-14 | R2: ERP Form. | S2: ERP Unit. | T2: ERP Cx. | U2: Eng. Form. | V2: Eng. Unit. | W2: Ativo / Inativo | X2: MS Anvisa | Y2: LP | Z2: COR | AA2: ODOR | AB2: ASPECTO | AC2: DENSIDADE | AD2: pH | AE2: TEOR DE ALCOOL | AF2: VISCOSIDADE | AG2: FAIXA DE PESO | AH2: Observações | AJ2: Viscosidade | AK2: Produção p/ Hora
B3: - | C3: DESODORANTE ROLLON ALGODÃO | D3: - | E3: - | F3: - | G3: - | H3: CORPORAL | I3: DESODORANTE | J3: VISCOSO | K3: =IFERROR(AVERAGEIFS('[1]Controle de Produção'!$E:$E,'[1]Controle de Produção'!$N:$N,E3,'[1]Controle de Produção'!$S:$S,J3,'[1]Controle de Produção'!$R:$R,I3),0) -> 802.46872 | L3: =IFERROR(AVERAGEIFS('[1]Controle de Produção'!$E:$E,'[1]Controle de Produção'!$S:$S,J3,'[1]Controle de Produção'!$R:$R,I3),0) -> 802.46872 | R3: FALSE | S3: FALSE | T3: FALSE | U3: FALSE | V3: FALSE | W3: Inativo | AJ3: VISCOSO | AK3: =AVERAGEIF(J:J,AJ3,L:L) -> 692.80427
B4: - | C4: DESODORANTE ROLLON LAVANDA | D4: - | E4: - | F4: - | G4: - | H4: CORPORAL | I4: DESODORANTE | J4: VISCOSO | K4: =IFERROR(AVERAGEIFS('[1]Controle de Produção'!$E:$E,'[1]Controle de Produção'!$N:$N,E4,'[1]Controle de Produção'!$S:$S,J4,'[1]Controle de Produção'!$R:$R,I4),0) -> 802.46872 | L4: =IFERROR(AVERAGEIFS('[1]Controle de Produção'!$E:$E,'[1]Controle de Produção'!$S:$S,J4,'[1]Controle de Produção'!$R:$R,I4),0) -> 802.46872 | R4: FALSE | S4: TRUE | T4: FALSE | U4: FALSE | V4: FALSE | W4: Inativo | AJ4: LÍQUIDO ESPESSO | AK4: =AVERAGEIF(J:J,AJ4,L:L) -> 803.34099
B5: - | C5: GEL BRILHO AMARELO | D5: - | E5: 30 | F5: ml | G5: BE MAGIC | H5: - | I5: GEL | J5: CREMOSO | K5: =IFERROR(AVERAGEIFS('[1]Controle de Produção'!$E:$E,'[1]Controle de Produção'!$N:$N,E5,'[1]Controle de Produção'!$S:$S,J5,'[1]Controle de Produção'!$R:$R,I5),0) -> 0 | L5: =IFERROR(AVERAGEIFS('[1]Controle de Produção'!$E:$E,'[1]Controle de Produção'!$S:$S,J5,'[1]Controle de Produção'!$R:$R,I5),0) -> 519.1326 | R5: FALSE | S5: TRUE | T5: FALSE | U5: FALSE | V5: FALSE | W5: Ativo | AJ5: LÍQUIDO | AK5: =AVERAGEIF(J:J,AJ5,L:L) -> 575.45103
B6: - | C6: GEL BRILHO ROSA | D6: - | E6: 30 | F6: ml | G6: BE MAGIC | H6: - | I6: GEL | J6: CREMOSO | K6: =IFERROR(AVERAGEIFS('[1]Controle de Produção'!$E:$E,'[1]Controle de Produção'!$N:$N,E6,'[1]Controle de Produção'!$S:$S,J6,'[1]Controle de Produção'!$R:$R,I6),0) -> 0 | L6: =IFERROR(AVERAGEIFS('[1]Controle de Produção'!$E:$E,'[1]Controle de Produção'!$S:$S,J6,'[1]Controle de Produção'!$R:$R,I6),0) -> 519.1326 | R6: FALSE | S6: TRUE | T6: FALSE | U6: FALSE | V6: FALSE | W6: Ativo | AJ6: CREMOSO | AK6: =AVERAGEIF(J:J,AJ6,L:L) -> 520.39541
B7: - | C7: GEL BRILHO ROXO | D7: - | E7: 30 | F7: ml | G7: BE MAGIC | H7: - | I7: GEL | J7: CREMOSO | K7: =IFERROR(AVERAGEIFS('[1]Controle de Produção'!$E:$E,'[1]Controle de Produção'!$N:$N,E7,'[1]Controle de Produção'!$S:$S,J7,'[1]Controle de Produção'!$R:$R,I7),0) -> 0 | L7: =IFERROR(AVERAGEIFS('[1]Controle de Produção'!$E:$E,'[1]Controle de Produção'!$S:$S,J7,'[1]Controle de Produção'!$R:$R,I7),0) -> 519.1326 | R7: FALSE | S7: TRUE | T7: FALSE | U7: FALSE | V7: FALSE | W7: Ativo | AJ7: DENSO | AK7: =AVERAGEIF(J:J,AJ7,L:L) -> 492.86342
B8: - | C8: GEL BRILHO VERMELHO | D8: - | E8: 30 | F8: ml | G8: BE MAGIC | H8: - | I8: GEL | J8: CREMOSO | K8: =IFERROR(AVERAGEIFS('[1]Controle de Produção'!$E:$E,'[1]Controle de Produção'!$N:$N,E8,'[1]Controle de Produção'!$S:$S,J8,'[1]Controle de Produção'!$R:$R,I8),0) -> 0 | L8: =IFERROR(AVERAGEIFS('[1]Controle de Produção'!$E:$E,'[1]Controle de Produção'!$S:$S,J8,'[1]Controle de Produção'!$R:$R,I8),0) -> 519.1326 | R8: FALSE | S8: TRUE | T8: FALSE | U8: FALSE | V8: FALSE | W8: Ativo
B9: - | C9: IMEDIATT LISS PASSO 1 | D9: - | E9: 1000 | F9: ml | G9: PRO STYLE | H9: CAPILAR | I9: FINALIZADOR | J9: CREMOSO | K9: =IFERROR(AVERAGEIFS('[1]Controle de Produção'!$E:$E,'[1]Controle de Produção'!$N:$N,E9,'[1]Controle de Produção'!$S:$S,J9,'[1]Controle de Produção'!$R:$R,I9),0) -> 0 | L9: =IFERROR(AVERAGEIFS('[1]Controle de Produção'!$E:$E,'[1]Controle de Produção'!$S:$S,J9,'[1]Controle de Produção'!$R:$R,I9),0) -> 571.39859 | R9: FALSE | S9: TRUE | T9: FALSE | U9: FALSE | V9: FALSE | W9: Ativo
B10: - | C10: IMEDIATT LISS PASSO 2 | D10: - | E10: 1000 | F10: ml | G10: PRO STYLE | H10: CAPILAR | I10: ESCOVA PROGRESSIVA | J10: CREMOSO | K10: =IFERROR(AVERAGEIFS('[1]Controle de Produção'!$E:$E,'[1]Controle de Produção'!$N:$N,E10,'[1]Controle de Produção'!$S:$S,J10,'[1]Controle de Produção'!$R:$R,I10),0) -> 0 | L10: =IFERROR(AVERAGEIFS('[1]Controle de Produção'!$E:$E,'[1]Controle de Produção'!$S:$S,J10,'[1]Controle de Produção'!$R:$R,I10),0) -> 0 | M10: 8 | R10: TRUE | S10: TRUE | T10: FALSE | U10: FALSE | V10: FALSE | W10: Ativo
B11: AMABBS01 | C11: BODY MIST TESOURO DO OASIS | D11: ARABE | E11: 250 | F11: ml | G11: AMEERATI | H11: PERFUMARIA | I11: BODY SPLASH | J11: LÍQUIDO | K11: =IFERROR(AVERAGEIFS('[1]Controle de Produção'!$E:$E,'[1]Controle de Produção'!$N:$N,E11,'[1]Controle de Produção'!$S:$S,J11,'[1]Controle de Produção'!$R:$R,I11),0) -> 616.88899 | L11: =IFERROR(AVERAGEIFS('[1]Controle de Produção'!$E:$E,'[1]Controle de Produção'!$S:$S,J11,'[1]Controle de Produção'!$R:$R,I11),0) -> 843.5878 | M11: 24 | R11: TRUE | S11: TRUE | T11: TRUE | U11: TRUE | V11: TRUE | W11: Ativo | Y11: 1.35
B12: AMABBS02 | C12: BODY MIST JARDINS DO ORIENTE | D12: ARABE | E12: 250 | F12: ml | G12: AMEERATI | H12: PERFUMARIA | I12: BODY SPLASH | J12: LÍQUIDO | K12: =IFERROR(AVERAGEIFS('[1]Controle de Produção'!$E:$E,'[1]Controle de Produção'!$N:$N,E12,'[1]Controle de Produção'!$S:$S,J12,'[1]Controle de Produção'!$R:$R,I12),0) -> 616.88899 | L12: =IFERROR(AVERAGEIFS('[1]Controle de Produção'!$E:$E,'[1]Controle de Produção'!$S:$S,J12,'[1]Controle de Produção'!$R:$R,I12),0) -> 843.5878 | M12: 24 | R12: TRUE | S12: TRUE | T12: TRUE | U12: TRUE | V12: TRUE | W12: Ativo | Y12: 1.35
B13: AMABBS03 | C13: BODY MIST FLOR DO DESERTO | D13: ARABE | E13: 250 | F13: ml | G13: AMEERATI | H13: PERFUMARIA | I13: BODY SPLASH | J13: LÍQUIDO | K13: =IFERROR(AVERAGEIFS('[1]Controle de Produção'!$E:$E,'[1]Controle de Produção'!$N:$N,E13,'[1]Controle de Produção'!$S:$S,J13,'[1]Controle de Produção'!$R:$R,I13),0) -> 616.88899 | L13: =IFERROR(AVERAGEIFS('[1]Controle de Produção'!$E:$E,'[1]Controle de Produção'!$S:$S,J13,'[1]Controle de Produção'!$R:$R,I13),0) -> 843.5878 | M13: 24 | R13: TRUE | S13: TRUE | T13: TRUE | U13: TRUE | V13: TRUE | W13: Ativo | Y13: 1.35
B14: AMABBS04 | C14: BODY MIST PEROLA DO DESERTO | D14: ARABE | E14: 250 | F14: ml | G14: AMEERATI | H14: PERFUMARIA | I14: BODY SPLASH | J14: LÍQUIDO | K14: =IFERROR(AVERAGEIFS('[1]Controle de Produção'!$E:$E,'[1]Controle de Produção'!$N:$N,E14,'[1]Controle de Produção'!$S:$S,J14,'[1]Controle de Produção'!$R:$R,I14),0) -> 616.88899 | L14: =IFERROR(AVERAGEIFS('[1]Controle de Produção'!$E:$E,'[1]Controle de Produção'!$S:$S,J14,'[1]Controle de Produção'!$R:$R,I14),0) -> 843.5878 | M14: 24 | R14: TRUE | S14: TRUE | T14: TRUE | U14: TRUE | V14: TRUE | W14: Ativo | Y14: 1.35
B15: AMABBS05 | C15: BODY MIST ROSA IMPERIAL | D15: ARABE | E15: 250 | F15: ml | G15: AMEERATI | H15: PERFUMARIA | I15: BODY SPLASH | J15: LÍQUIDO | K15: =IFERROR(AVERAGEIFS('[1]Controle de Produção'!$E:$E,'[1]Controle de Produção'!$N:$N,E15,'[1]Controle de Produção'!$S:$S,J15,'[1]Controle de Produção'!$R:$R,I15),0) -> 616.88899 | L15: =IFERROR(AVERAGEIFS('[1]Controle de Produção'!$E:$E,'[1]Controle de Produção'!$S:$S,J15,'[1]Controle de Produção'!$R:$R,I15),0) -> 843.5878 | M15: 24 | R15: TRUE | S15: TRUE | T15: TRUE | U15: TRUE | V15: TRUE | W15: Ativo | Y15: 1.35
B16: AMABBS06 | C16: BODY MIST ENCANTO PERSA | D16: ARABE | E16: 250 | F16: ml | G16: AMEERATI | H16: PERFUMARIA | I16: BODY SPLASH | J16: LÍQUIDO | K16: =IFERROR(AVERAGEIFS('[1]Controle de Produção'!$E:$E,'[1]Controle de Produção'!$N:$N,E16,'[1]Controle de Produção'!$S:$S,J16,'[1]Controle de Produção'!$R:$R,I16),0) -> 616.88899 | L16: =IFERROR(AVERAGEIFS('[1]Controle de Produção'!$E:$E,'[1]Controle de Produção'!$S:$S,J16,'[1]Controle de Produção'!$R:$R,I16),0) -> 843.5878 | M16: 24 | R16: TRUE | S16: TRUE | T16: TRUE | U16: TRUE | V16: TRUE | W16: Ativo | Y16: 1.35
B17: AMABBS07 | C17: BODY MIST MEL DE ESPECIARIAS | D17: ARABE | E17: 250 | F17: ml | G17: AMEERATI | H17: PERFUMARIA | I17: BODY SPLASH | J17: LÍQUIDO | K17: =IFERROR(AVERAGEIFS('[1]Controle de Produção'!$E:$E,'[1]Controle de Produção'!$N:$N,E17,'[1]Controle de Produção'!$S:$S,J17,'[1]Controle de Produção'!$R:$R,I17),0) -> 616.88899 | L17: =IFERROR(AVERAGEIFS('[1]Controle de Produção'!$E:$E,'[1]Controle de Produção'!$S:$S,J17,'[1]Controle de Produção'!$R:$R,I17),0) -> 843.5878 | M17: 24 | R17: TRUE | S17: TRUE | T17: TRUE | U17: TRUE | V17: TRUE | W17: Ativo | Y17: 1.35
B18: AMABBS08 | C18: BODY MIST RARO ELIXIR | D18: ARABE | E18: 250 | F18: ml | G18: AMEERATI | H18: PERFUMARIA | I18: BODY SPLASH | J18: LÍQUIDO | K18: =IFERROR(AVERAGEIFS('[1]Controle de Produção'!$E:$E,'[1]Controle de Produção'!$N:$N,E18,'[1]Controle de Produção'!$S:$S,J18,'[1]Controle de Produção'!$R:$R,I18),0) -> 616.88899 | L18: =IFERROR(AVERAGEIFS('[1]Controle de Produção'!$E:$E,'[1]Controle de Produção'!$S:$S,J18,'[1]Controle de Produção'!$R:$R,I18),0) -> 843.5878 | M18: 24 | R18: TRUE | S18: TRUE | T18: TRUE | U18: TRUE | V18: TRUE | W18: Ativo | Y18: 1.35
B19: AMABHD01 | C19: BODY CREAM TESOURO DO OASIS | D19: ARABE | E19: 240 | F19: ml | G19: AMEERATI | H19: CORPORAL | I19: CREME HIDRATANTE | J19: CREMOSO | K19: =IFERROR(AVERAGEIFS('[1]Controle de Produção'!$E:$E,'[1]Controle de Produção'!$N:$N,E19,'[1]Controle de Produção'!$S:$S,J19,'[1]Controle de Produção'!$R:$R,I19),0) -> 639.01476 | L19: =IFERROR(AVERAGEIFS('[1]Controle de Produção'!$E:$E,'[1]Controle de Produção'!$S:$S,J19,'[1]Controle de Produção'!$R:$R,I19),0) -> 613.39886 | M19: 24 | R19: TRUE | S19: TRUE | T19: TRUE | U19: TRUE | V19: TRUE | W19: Ativo | Y19: 1.48
B20: AMABHD02 | C20: BODY CREAM JARDINS DO ORIENTE | D20: ARABE | E20: 240 | F20: ml | G20: AMEERATI | H20: CORPORAL | I20: CREME HIDRATANTE | J20: CREMOSO | K20: =IFERROR(AVERAGEIFS('[1]Controle de Produção'!$E:$E,'[1]Controle de Produção'!$N:$N,E20,'[1]Controle de Produção'!$S:$S,J20,'[1]Controle de Produção'!$R:$R,I20),0) -> 639.01476 | L20: =IFERROR(AVERAGEIFS('[1]Controle de Produção'!$E:$E,'[1]Controle de Produção'!$S:$S,J20,'[1]Controle de Produção'!$R:$R,I20),0) -> 613.39886 | M20: 24 | R20: TRUE | S20: TRUE | T20: TRUE | U20: TRUE | V20: TRUE | W20: Ativo | Y20: 1.48
B21: AMABHD03 | C21: BODY CREAM FLOR DO DESERTO | D21: ARABE | E21: 240 | F21: ml | G21: AMEERATI | H21: CORPORAL | I21: CREME HIDRATANTE | J21: CREMOSO | K21: =IFERROR(AVERAGEIFS('[1]Controle de Produção'!$E:$E,'[1]Controle de Produção'!$N:$N,E21,'[1]Controle de Produção'!$S:$S,J21,'[1]Controle de Produção'!$R:$R,I21),0) -> 639.01476 | L21: =IFERROR(AVERAGEIFS('[1]Controle de Produção'!$E:$E,'[1]Controle de Produção'!$S:$S,J21,'[1]Controle de Produção'!$R:$R,I21),0) -> 613.39886 | M21: 24 | R21: TRUE | S21: TRUE | T21: TRUE | U21: TRUE | V21: TRUE | W21: Ativo | Y21: 1.48
B22: AMABHD04 | C22: BODY CREAM PEROLA DO DESERTO | D22: ARABE | E22: 240 | F22: ml | G22: AMEERATI | H22: CORPORAL | I22: CREME HIDRATANTE | J22: CREMOSO | K22: =IFERROR(AVERAGEIFS('[1]Controle de Produção'!$E:$E,'[1]Controle de Produção'!$N:$N,E22,'[1]Controle de Produção'!$S:$S,J22,'[1]Controle de Produção'!$R:$R,I22),0) -> 639.01476 | L22: =IFERROR(AVERAGEIFS('[1]Controle de Produção'!$E:$E,'[1]Controle de Produção'!$S:$S,J22,'[1]Controle de Produção'!$R:$R,I22),0) -> 613.39886 | M22: 24 | R22: TRUE | S22: TRUE | T22: TRUE | U22: TRUE | V22: TRUE | W22: Ativo | Y22: 1.48
... B58: AMNCHD08 | C58: BODY CREAM SUBLIME CEREJA | D58: NICHE | E58: 240 | F58: ml | G58: AMEERATI | H58: CORPORAL | I58: CREME HIDRATANTE | J58: CREMOSO | K58: =IFERROR(AVERAGEIFS('[1]Controle de Produção'!$E:$E,'[1]Controle de Produção'!$N:$N,E58,'[1]Controle de Produção'!$S:$S,J58,'[1]Controle de Produção'!$R:$R,I58),0) -> 639.01476 | L58: =IFERROR(AVERAGEIFS('[1]Controle de Produção'!$E:$E,'[1]Controle de Produção'!$S:$S,J58,'[1]Controle de Produção'!$R:$R,I58),0) -> 613.39886 | M58: 24 | R58: TRUE | S58: TRUE | T58: TRUE | U58: TRUE | V58: TRUE | W58: Ativo | Y58: 1.48
B59: BBPF0004 | C59: PERFUME CAPILAR ZAHRA | E59: 60 | F59: ml | G59: BRIA BEAUTY | H59: PERFUMARIA | I59: PERFUME CAPILAR | J59: LÍQUIDO ESPESSO | K59: =IFERROR(AVERAGEIFS('[1]Controle de Produção'!$E:$E,'[1]Controle de Produção'!$N:$N,E59,'[1]Controle de Produção'!$S:$S,J59,'[1]Controle de Produção'!$R:$R,I59),0) -> 674.69639 | L59: =IFERROR(AVERAGEIFS('[1]Controle de Produção'!$E:$E,'[1]Controle de Produção'!$S:$S,J59,'[1]Controle de Produção'!$R:$R,I59),0) -> 674.69639 | M59: 120 | O59: BB0130 | R59: TRUE | S59: TRUE | T59: TRUE | U59: TRUE | V59: TRUE | W59: Ativo | Y59: 1.57
B60: BBSJBS01 | C60: BODY SPLASH SOL TROPICAL 61 200ml | D60: SOL DE JANEIRO | E60: 200 | F60: ml | G60: BRIA BEAUTY | H60: PERFUMARIA | I60: BODY SPLASH | J60: LÍQUIDO | K60: =IFERROR(AVERAGEIFS('[1]Controle de Produção'!$E:$E,'[1]Controle de Produção'!$N:$N,E60,'[1]Controle de Produção'!$S:$S,J60,'[1]Controle de Produção'!$R:$R,I60),0) -> 936.45348 | L60: =IFERROR(AVERAGEIFS('[1]Controle de Produção'!$E:$E,'[1]Controle de Produção'!$S:$S,J60,'[1]Controle de Produção'!$R:$R,I60),0) -> 843.5878 | M60: 48 | O60: BB0088 | R60: TRUE | S60: TRUE | T60: TRUE | U60: TRUE | V60: TRUE | W60: Ativo | Y60: 1.47
B61: BBSJBS01-2 | C61: BODY SPLASH SOL TROPICAL 61 120ml | D61: SOL DE JANEIRO | E61: 120 | F61: ml | G61: BRIA BEAUTY | H61: PERFUMARIA | I61: BODY SPLASH | J61: LÍQUIDO | K61: =IFERROR(AVERAGEIFS('[1]Controle de Produção'!$E:$E,'[1]Controle de Produção'!$N:$N,E61,'[1]Controle de Produção'!$S:$S,J61,'[1]Controle de Produção'!$R:$R,I61),0) -> 907.28092 | L61: =IFERROR(AVERAGEIFS('[1]Controle de Produção'!$E:$E,'[1]Controle de Produção'!$S:$S,J61,'[1]Controle de Produção'!$R:$R,I61),0) -> 843.5878 | M61: 80 | O61: BB0084 | R61: TRUE | S61: TRUE | T61: TRUE | U61: TRUE | V61: TRUE | W61: Ativo | Y61: 1.08
B62: BBSJBS02 | C62: BODY SPLASH SOL TROPICAL 86 200ml | D62: SOL DE JANEIRO | E62: 200 | F62: ml | G62: BRIA BEAUTY | H62: PERFUMARIA | I62: BODY SPLASH | J62: LÍQUIDO | K62: =IFERROR(AVERAGEIFS('[1]Controle de Produção'!$E:$E,'[1]Controle de Produção'!$N:$N,E62,'[1]Controle de Produção'!$S:$S,J62,'[1]Controle de Produção'!$R:$R,I62),0) -> 936.45348 | L62: =IFERROR(AVERAGEIFS('[1]Controle de Produção'!$E:$E,'[1]Controle de Produção'!$S:$S,J62,'[1]Controle de Produção'!$R:$R,I62),0) -> 843.5878 | M62: 48 | O62: BB0089 | R62: TRUE | S62: TRUE | T62: TRUE | U62: TRUE | V62: TRUE | W62: Ativo | Y62: 1.47
B63: BBSJBS02-2 | C63: BODY SPLASH SOL TROPICAL 86 120ml | D63: SOL DE JANEIRO | E63: 120 | F63: ml | G63: BRIA BEAUTY | H63: PERFUMARIA | I63: BODY SPLASH | J63: LÍQUIDO | K63: =IFERROR(AVERAGEIFS('[1]Controle de Produção'!$E:$E,'[1]Controle de Produção'!$N:$N,E63,'[1]Controle de Produção'!$S:$S,J63,'[1]Controle de Produção'!$R:$R,I63),0) -> 907.28092 | L63: =IFERROR(AVERAGEIFS('[1]Controle de Produção'!$E:$E,'[1]Controle de Produção'!$S:$S,J63,'[1]Controle de Produção'!$R:$R,I63),0) -> 843.5878 | M63: 80 | O63: BB0085 | R63: TRUE | S63: TRUE | T63: TRUE | U63: TRUE | V63: TRUE | W63: Ativo | Y63: 1.08
B64: BBSJBS03 | C64: BODY SPLASH LUNAR 200ml | D64: SOL DE JANEIRO | E64: 200 | F64: ml | G64: BRIA BEAUTY | H64: PERFUMARIA | I64: BODY SPLASH | J64: LÍQUIDO | K64: =IFERROR(AVERAGEIFS('[1]Controle de Produção'!$E:$E,'[1]Controle de Produção'!$N:$N,E64,'[1]Controle de Produção'!$S:$S,J64,'[1]Controle de Produção'!$R:$R,I64),0) -> 936.45348 | L64: =IFERROR(AVERAGEIFS('[1]Controle de Produção'!$E:$E,'[1]Controle de Produção'!$S:$S,J64,'[1]Controle de Produção'!$R:$R,I64),0) -> 843.5878 | M64: 48 | O64: BB0090 | R64: TRUE | S64: TRUE | T64: TRUE | U64: TRUE | V64: TRUE | W64: Ativo | Y64: 1.47
B65: BBSJBS03-2 | C65: BODY SPLASH LUNAR 120ml | D65: SOL DE JANEIRO | E65: 120 | F65: ml | G65: BRIA BEAUTY | H65: PERFUMARIA | I65: BODY SPLASH | J65: LÍQUIDO | K65: =IFERROR(AVERAGEIFS('[1]Controle de Produção'!$E:$E,'[1]Controle de Produção'!$N:$N,E65,'[1]Controle de Produção'!$S:$S,J65,'[1]Controle de Produção'!$R:$R,I65),0) -> 907.28092 | L65: =IFERROR(AVERAGEIFS('[1]Controle de Produção'!$E:$E,'[1]Controle de Produção'!$S:$S,J65,'[1]Controle de Produção'!$R:$R,I65),0) -> 843.5878 | M65: 80 | O65: BB0086 | R65: TRUE | S65: TRUE | T65: TRUE | U65: TRUE | V65: TRUE | W65: Ativo | Y65: 1.08
B66: BBSJBS04-2 | C66: BODY SPLASH SOL TROPICAL 58 120ml | D66: SOL DE JANEIRO | E66: 120 | F66: ml | G66: BRIA BEAUTY | H66: PERFUMARIA | I66: BODY SPLASH | J66: LÍQUIDO | K66: =IFERROR(AVERAGEIFS('[1]Controle de Produção'!$E:$E,'[1]Controle de Produção'!$N:$N,E66,'[1]Controle de Produção'!$S:$S,J66,'[1]Controle de Produção'!$R:$R,I66),0) -> 907.28092 | L66: =IFERROR(AVERAGEIFS('[1]Controle de Produção'!$E:$E,'[1]Controle de Produção'!$S:$S,J66,'[1]Controle de Produção'!$R:$R,I66),0) -> 843.5878 | M66: 80 | O66: BB0083 | R66: TRUE | S66: TRUE | T66: TRUE | U66: TRUE | V66: TRUE | W66: Ativo | Y66: 1.08
B67: BBSJBS05-2 | C67: BODY SPLASH ZAHRA 120ml | D67: SOL DE JANEIRO | E67: 120 | F67: ml | G67: BRIA BEAUTY | H67: PERFUMARIA | I67: BODY SPLASH | J67: LÍQUIDO | K67: =IFERROR(AVERAGEIFS('[1]Controle de Produção'!$E:$E,'[1]Controle de Produção'!$N:$N,E67,'[1]Controle de Produção'!$S:$S,J67,'[1]Controle de Produção'!$R:$R,I67),0) -> 907.28092 | L67: =IFERROR(AVERAGEIFS('[1]Controle de Produção'!$E:$E,'[1]Controle de Produção'!$S:$S,J67,'[1]Controle de Produção'!$R:$R,I67),0) -> 843.5878 | M67: 80 | O67: BB0087 | R67: TRUE | S67: TRUE | T67: TRUE | U67: TRUE | V67: TRUE | W67: Ativo | Y67: 1.08
B68: BBSJPF01 | C68: PERFUME CAPILAR SOL TROPICAL 61 | D68: SOL DE JANEIRO | E68: 60 | F68: ml | G68: BRIA BEAUTY | H68: PERFUMARIA | I68: PERFUME CAPILAR | J68: LÍQUIDO ESPESSO | K68: =IFERROR(AVERAGEIFS('[1]Controle de Produção'!$E:$E,'[1]Controle de Produção'!$N:$N,E68,'[1]Controle de Produção'!$S:$S,J68,'[1]Controle de Produção'!$R:$R,I68),0) -> 674.69639 | L68: =IFERROR(AVERAGEIFS('[1]Controle de Produção'!$E:$E,'[1]Controle de Produção'!$S:$S,J68,'[1]Controle de Produção'!$R:$R,I68),0) -> 674.69639 | M68: 120 | O68: BB0080 | R68: TRUE | S68: TRUE | T68: TRUE | U68: TRUE | V68: TRUE | W68: Ativo | Y68: 1.57
B69: BBSJPF02 | C69: PERFUME CAPILAR SOL TROPICAL 86 | D69: SOL DE JANEIRO | E69: 60 | F69: ml | G69: BRIA BEAUTY | H69: PERFUMARIA | I69: PERFUME CAPILAR | J69: LÍQUIDO ESPESSO | K69: =IFERROR(AVERAGEIFS('[1]Controle de Produção'!$E:$E,'[1]Controle de Produção'!$N:$N,E69,'[1]Controle de Produção'!$S:$S,J69,'[1]Controle de Produção'!$R:$R,I69),0) -> 674.69639 | L69: =IFERROR(AVERAGEIFS('[1]Controle de Produção'!$E:$E,'[1]Controle de Produção'!$S:$S,J69,'[1]Controle de Produção'!$R:$R,I69),0) -> 674.69639 | M69: 120 | O69: BB0081 | R69: TRUE | S69: TRUE | T69: TRUE | U69: TRUE | V69: TRUE | W69: Ativo | Y69: 1.57
B70: BBSJPF03 | C70: PERFUME CAPILAR LUNAR | D70: SOL DE JANEIRO | E70: 60 | F70: ml | G70: BRIA BEAUTY | H70: PERFUMARIA | I70: PERFUME CAPILAR | J70: LÍQUIDO ESPESSO | K70: =IFERROR(AVERAGEIFS('[1]Controle de Produção'!$E:$E,'[1]Controle de Produção'!$N:$N,E70,'[1]Controle de Produção'!$S:$S,J70,'[1]Controle de Produção'!$R:$R,I70),0) -> 674.69639 | L70: =IFERROR(AVERAGEIFS('[1]Controle de Produção'!$E:$E,'[1]Controle de Produção'!$S:$S,J70,'[1]Controle de Produção'!$R:$R,I70),0) -> 674.69639 | M70: 120 | O70: BB0082 | R70: TRUE | S70: TRUE | T70: TRUE | U70: TRUE | V70: TRUE | W70: Ativo | Y70: 1.57
B71: BFBBBS01 | C71: BODY SPLASH BIO BALM EUPHORIA PINK | D71: B BALM | E71: 200 | F71: ml | G71: BIOFLORA | H71: PERFUMARIA | I71: BODY SPLASH | J71: LÍQUIDO | K71: =IFERROR(AVERAGEIFS('[1]Controle de Produção'!$E:$E,'[1]Controle de Produção'!$N:$N,E71,'[1]Controle de Produção'!$S:$S,J71,'[1]Controle de Produção'!$R:$R,I71),0) -> 936.45348 | L71: =IFERROR(AVERAGEIFS('[1]Controle de Produção'!$E:$E,'[1]Controle de Produção'!$S:$S,J71,'[1]Controle de Produção'!$R:$R,I71),0) -> 843.5878 | M71: 12 | R71: TRUE | S71: TRUE | T71: TRUE | U71: TRUE | V71: TRUE | W71: Ativo | Y71: 1.7
B72: BFBBBS02 | C72: BODY SPLASH BIO BALM INFINITY ROUGE | D72: B BALM | E72: 200 | F72: ml | G72: BIOFLORA | H72: PERFUMARIA | I72: BODY SPLASH | J72: LÍQUIDO | K72: =IFERROR(AVERAGEIFS('[1]Controle de Produção'!$E:$E,'[1]Controle de Produção'!$N:$N,E72,'[1]Controle de Produção'!$S:$S,J72,'[1]Controle de Produção'!$R:$R,I72),0) -> 936.45348 | L72: =IFERROR(AVERAGEIFS('[1]Controle de Produção'!$E:$E,'[1]Controle de Produção'!$S:$S,J72,'[1]Controle de Produção'!$R:$R,I72),0) -> 843.5878 | M72: 12 | R72: TRUE | S72: TRUE | T72: TRUE | U72: TRUE | V72: TRUE | W72: Ativo | Y72: 1.7
B73: BFBBBS03 | C73: BODY SPLASH BIO BALM ROSÉ ABSOLUT | D73: B BALM | E73: 200 | F73: ml | G73: BIOFLORA | H73: PERFUMARIA | I73: BODY SPLASH | J73: LÍQUIDO | K73: =IFERROR(AVERAGEIFS('[1]Controle de Produção'!$E:$E,'[1]Controle de Produção'!$N:$N,E73,'[1]Controle de Produção'!$S:$S,J73,'[1]Controle de Produção'!$R:$R,I73),0) -> 936.45348 | L73: =IFERROR(AVERAGEIFS('[1]Controle de Produção'!$E:$E,'[1]Controle de Produção'!$S:$S,J73,'[1]Controle de Produção'!$R:$R,I73),0) -> 843.5878 | M73: 12 | R73: TRUE | S73: TRUE | T73: TRUE | U73: TRUE | V73: TRUE | W73: Ativo | Y73: 1.7
B74: BFBBBS04 | C74: BODY SPLASH BIO BALM SKINLIGHT | D74: B BALM | E74: 200 | F74: ml | G74: BIOFLORA | H74: PERFUMARIA | I74: BODY SPLASH | J74: LÍQUIDO | K74: =IFERROR(AVERAGEIFS('[1]Controle de Produção'!$E:$E,'[1]Controle de Produção'!$N:$N,E74,'[1]Controle de Produção'!$S:$S,J74,'[1]Controle de Produção'!$R:$R,I74),0) -> 936.45348 | L74: =IFERROR(AVERAGEIFS('[1]Controle de Produção'!$E:$E,'[1]Controle de Produção'!$S:$S,J74,'[1]Controle de Produção'!$R:$R,I74),0) -> 843.5878 | M74: 12 | R74: TRUE | S74: TRUE | T74: TRUE | U74: TRUE | V74: TRUE | W74: Ativo | Y74: 1.7
B75: BFBBBS05 | C75: BODY SPLASH BIO BALM SUNRISE MUSE | D75: B BALM | E75: 200 | F75: ml | G75: BIOFLORA | H75: PERFUMARIA | I75: BODY SPLASH | J75: LÍQUIDO | K75: =IFERROR(AVERAGEIFS('[1]Controle de Produção'!$E:$E,'[1]Controle de Produção'!$N:$N,E75,'[1]Controle de Produção'!$S:$S,J75,'[1]Controle de Produção'!$R:$R,I75),0) -> 936.45348 | L75: =IFERROR(AVERAGEIFS('[1]Controle de Produção'!$E:$E,'[1]Controle de Produção'!$S:$S,J75,'[1]Controle de Produção'!$R:$R,I75),0) -> 843.5878 | M75: 12 | R75: TRUE | S75: TRUE | T75: TRUE | U75: TRUE | V75: TRUE | W75: Ativo | Y75: 1.7
B76: BFBBBS06 | C76: BODY SPLASH BIO BALM V DREAM | D76: B BALM | E76: 200 | F76: ml | G76: BIOFLORA | H76: PERFUMARIA | I76: BODY SPLASH | J76: LÍQUIDO | K76: =IFERROR(AVERAGEIFS('[1]Controle de Produção'!$E:$E,'[1]Controle de Produção'!$N:$N,E76,'[1]Controle de Produção'!$S:$S,J76,'[1]Controle de Produção'!$R:$R,I76),0) -> 936.45348 | L76: =IFERROR(AVERAGEIFS('[1]Controle de Produção'!$E:$E,'[1]Controle de Produção'!$S:$S,J76,'[1]Controle de Produção'!$R:$R,I76),0) -> 843.5878 | M76: 12 | R76: TRUE | S76: TRUE | T76: TRUE | U76: TRUE | V76: TRUE | W76: Ativo | Y76: 1.7
...

Sheet Sheet2
B2: CAT [3] | C2: Forma | D2: Observação
B3: SER | C3: Sérum | D3: fluido concentrado
B4: AGU | C4: Água (facial/corporal) | D4: água termal, micelar, de limpeza
B5: BRU | C5: Bruma / Névoa | D5: sprays perfumados/tratantes
B6: TON | C6: Tônico | D6: aplicação com algodão
B7: ESP | C7: Espuma | D7: limpeza, higiene
B8: HID | C8: Hidratante | D8: textura (creme/gel/loção) em campo
B9: GEL | C9: Gel | D9: quando processo difere do hidratante
B10: OLE | C10: Óleo | D10: corporal, capilar, facial
B11: MAN | C11: Manteiga / Bálsamo | D11: base anidra sólida-pastosa
B12: SAB | C12: Sabonete líquido
B13: SBB | C13: Sabonete em barra | D13: saponificação/extrusão
B14: BSP | C14: Body Splash
B15: PRF | C15: Perfume | D15: concentração (EDP/EDT/deo) em campo
B16: SHA | C16: Shampoo
B17: CON | C17: Condicionador
B18: MAS | C18: Máscara (capilar/facial)
B19: LEA | C19: Leave-in / Finalizador
B20: ESF | C20: Esfoliante | D20: esfoliação química/enzimática
B21: SCR | C21: Scrub | D21: esfoliação mecânica/abrasiva
B22: POM | C22: Pomada / Creme anidro
B23: PRO | C23: Protetor solar | D23: regulatoriamente à parte

Sheet MPs
B2: SKU | C2: Descrição do Item | D2: REFERÊNCIA | E2: U.M. | F2: CLIENTE | G2: GRUPO | H2: SUB-GRUPO | I2: OBSERVAÇÕES | L2: Grupo | M2: Sub-Grupo
B3: ECXMR01 | C3: CAIXA DE EMBARQUE | D3: CAIXA BODY SPLASH ARABE | E3: UN | G3: EMBALAGEM | L3: PRODUTO DE VENDA | M3: GERAL
B4: MP-ALC-001 | C4: ALCOOL ETILICO HIDRATADO REFINADO | D4: ETANOL | E4: kg | G4: MATERIA PRIMA | H4: ALCOOL | L4: MATERIA PRIMA | M4: BASE
B5: MP-BASE-IPQ-001 | C5: Base 12 | D5: BASE | E5: kg | G5: MATERIA PRIMA | H5: BASE | L5: EMBALAGEM | M5: CORANTES
B6: MP-BASE-IPQ-002 | C6: Base 15 | D6: BASE | E6: kg | G6: MATERIA PRIMA | H6: BASE | L6: MAO DE OBRA | M6: FRAGRANCIAS
B7: MP-BASE-IPQ-003 | C7: Base 18 | D7: BASE HAIR | E7: kg | G7: MATERIA PRIMA | H7: BASE | L7: MATERIAL ADMINISTRATIVO | M7: ALCOOL
B8: MP-BASE-IPQ-004 | C8: Basen16 | D8: BASE SKIN | E8: kg | G8: MATERIA PRIMA | H8: BASE | L8: MAQUINA E EQUIPAMENTOS
B9: MP-CONS-001 | C9: METIL CLORO ISOTIAZOLINONAS | D9: CONSERVANTES | E9: kg | G9: MATERIA PRIMA | L9: MATERIAL DE MANUTENÇÃO
B10: MPCN002 | C10: FENOXIETANOL | D10: CONSERVANTES | E10: kg | G10: MATERIA PRIMA | H10: GERAL | L10: PRODUTO SEMI-ACABADO
B11: MPCR004 | C11: Corante Violet 43 | E11: kg | G11: MATERIA PRIMA | H11: CORANTES | L11: TERCEIRIZACÇÃO
B12: MPCR01 | C12: CORANTE EM PO VERMELHO | D12: CORANTE VERMELHO BORDO - CORIN | E12: kg | G12: MATERIA PRIMA | H12: CORANTES | L12: FULL-SERVICE
B13: MPCR02 | C13: CORANTE EM PO AMARELO | D13: CORANTE AMARELO TARTRAZINA - CORIN | E13: kg | G13: MATERIA PRIMA | H13: CORANTES
B14: MPCR03 | C14: CORANTE EM PO AZUL | D14: CORANTE AZUL DE METILENO - CORIN | E14: kg | G14: MATERIA PRIMA | H14: CORANTES
B15: MPES041 | C15: Atena | E15: kg | G15: MATERIA PRIMA | H15: FRAGRANCIAS
B16: MPGGES01 | C16: ESSENCIA TAMARA E DAMASCO PLUS | D16: GF43850 | E16: kg | G16: MATERIA PRIMA | H16: FRAGRANCIAS
B17: MPGGES02 | C17: ESSENCIA GLOWING | D17: GF43848 | E17: kg | G17: MATERIA PRIMA | H17: FRAGRANCIAS
B18: MPGGES03 | C18: ESSENCIA CLEOPATRA PLUS | D18: GF43849 | E18: kg | G18: MATERIA PRIMA | H18: FRAGRANCIAS
B19: MPGGES04 | C19: ESSENCIA ROYALTY | D19: GF43847 | E19: kg | G19: MATERIA PRIMA | H19: FRAGRANCIAS
B20: MPGGES05 | C20: ESSENCIA DESERT | D20: GF45004 | E20: kg | G20: MATERIA PRIMA | H20: FRAGRANCIAS
B21: MPGGES06 | C21: ESSENCIA LUMUS | D21: GF46329 | E21: kg | G21: MATERIA PRIMA | H21: FRAGRANCIAS
B22: MPGGES07 | C22: ESSENCIA PINK SPARKLING | D22: GF46330 | E22: kg | G22: MATERIA PRIMA | H22: FRAGRANCIAS
B23: MPGGES08 | C23: ESSENCIA ONLY ONE | D23: GF46334 | E23: kg | G23: MATERIA PRIMA | H23: FRAGRANCIAS
B24: MPGGES09 | C24: ESSENCIA THE NIGHT | D24: GF46333 | E24: kg | G24: MATERIA PRIMA | H24: FRAGRANCIAS
B25: MPGGES10 | C25: ESSENCIA DIVINE | D25: GF46331 | E25: kg | G25: MATERIA PRIMA | H25: FRAGRANCIAS
B26: MPGGES11 | C26: ESSENCIA SWEET VANILLA | D26: GF46332 | E26: kg | G26: MATERIA PRIMA | H26: FRAGRANCIAS
B27: MPGGES12 | C27: ESSENCIA BEAST MAN | D27: GF45664 | E27: kg | G27: MATERIA PRIMA | H27: FRAGRANCIAS
... B65: MPGR016 | C65: D- Panthenol | D65: HIDRATANTE | E65: kg | G65: MATERIA PRIMA | H65: GERAL
B66: MPGR017 | C66: Dietilftalato | D66: SOLVENTE | E66: kg | G66: MATERIA PRIMA | H66: GERAL | I66: Fixador p/ perfumes
B67: MPGR018 | C67: EDTA | D67: ESTABILIZADOR | E67: kg | G67: MATERIA PRIMA | H67: GERAL
B68: MPGR019 | C68: Extrato Glicólico | D68: HIDRATANTE | E68: kg | G68: MATERIA PRIMA | H68: GERAL
B69: MPGR020 | C69: Glicerina | D69: HIDRATANTE | E69: kg | G69: MATERIA PRIMA | H69: GERAL
B70: MPGR021 | C70: Hidróxido de Alúminio | D70: PROTETOR DE PELE | E70: kg | G70: MATERIA PRIMA | H70: GERAL
B71: MPGR022 | C71: Hidroxietilcellulose | D71: REGULADOR DE VISCOSIDADE | E71: kg | G71: MATERIA PRIMA | H71: GERAL
B72: MPGR023 | C72: Lauril | D72: TENSOATIVO | E72: kg | G72: MATERIA PRIMA | H72: GERAL
B73: MPGR024 | C73: Mentol Cristal | D73: AROMATIZANTE | E73: kg | G73: MATERIA PRIMA | H73: GERAL
B74: MPGR025 | C74: Mica Gold | D74: ADITIVO VISUAL | E74: kg | G74: MATERIA PRIMA | H74: GERAL
B75: MPGR026 | C75: Parafina | D75: HIDRATANTE | E75: kg | G75: MATERIA PRIMA | H75: GERAL
B76: MPGR027 | C76: Peg 150 | D76: ESPESSANTE | E76: kg | G76: MATERIA PRIMA | H76: GERAL
B77: MPGR028 | C77: Silicone 245 | D77: HIDRATANTE | E77: kg | G77: MATERIA PRIMA | H77: GERAL
B78: MPGR029 | C78: Quartenário 50% | D78: AGENTE CONDICIONANTE | E78: kg | G78: MATERIA PRIMA | H78: GERAL
...

Sheet Insumos
B2: SKU | C2: Descrição do Item | D2: REFERÊNCIA | E2: CLIENTE | F2: GRUPO | G2: SUB-GRUPO | H2: OBSERVAÇÕES | K2: Grupo | L2: Sub-Grupo
B3: ECXMR01 | C3: CAIXA DE EMBARQUE | D3: CAIXA BODY SPLASH ARABE | F3: EMBALAGEM | G3: CAIXA DE EMBARQUE | K3: EMBALAGEM | L3: FRASCO
B4: EMFR - DPBS/HD | C4: FRASCO PET CRISTAL 120ML 24410 - SOROPACK | D4: BODY SPLASH E HIDRANTES | F4: EMBALAGEM | G4: FRASCO | L4: ROTULO
B5: EMFR - GLMKAM06 | C5: FRASCO PET GRAVADO BABA GLOW 300 ml 24410 - SOROPACK | D5: ÁGUA MICELAR GLOW MAKE UP | F5: EMBALAGEM | G5: FRASCO | L5: TAMPA
B6: EMFR - GLMKAM05 | C6: FRASCO PET GRAVADO ROSA MOSQUETA 300 ml 24410 - SOROPACK | D6: ÁGUA MICELAR GLOW MAKE UP | F6: EMBALAGEM | G6: FRASCO | L6: SOBRETAMPA
B7: EMFR - GLMKAM04 | C7: FRASCO PET GRAVADO COLAGENO 300 ml 24410 - SOROPACK | D7: ÁGUA MICELAR GLOW MAKE UP | F7: EMBALAGEM | G7: FRASCO | L7: CARTUCHO
B8: EMFR - GLMKAM03 | C8: FRASCO PET GRAVADO CARVAO ATIVADO 300 ml 24410 - SOROPACK | D8: ÁGUA MICELAR GLOW MAKE UP | F8: EMBALAGEM | G8: FRASCO | L8: CELOFANE
B9: EMFR - GLMKAM02 | C9: FRASCO PET GRAVADO ACIDO HIALURONICO 300 ml 24410 - SOROPACK | D9: ÁGUA MICELAR GLOW MAKE UP | F9: EMBALAGEM | G9: FRASCO | L9: SLEEVE
B10: EMFR - GLMKAM01 | C10: FRASCO PET GRAVADO 3 EM 1 300 ml 24410 - SOROPACK | D10: ÁGUA MICELAR GLOW MAKE UP | F10: EMBALAGEM | G10: FRASCO | L10: VALVULA
B11: EMSL - DPGLBS | C11: SLEEVE PARA BODY SPLASH | D11: BODY SPLASH DAPOP | F11: EMBALAGEM | G11: SLEEVE | L11: CAIXA DE EMBARQUE
B12: EMET - ET01 | C12: ETIQUETA 90x55 | D12: ETIQUETA PARA CAIXAS | F12: EMBALAGEM | G12: ETIQUETA | L12: ETIQUETA
B13: EMRT - BFBBBS06 | C13: ROTULO BODY SPLASH BIO BALM V DREAM | D13: ROTULO BODY SPLASH B BALM BIOFLORA | F13: EMBALAGEM | G13: ROTULO
B14: EMRT - BFBBBS05 | C14: ROTULO BODY SPLASH BIO BALM SUNRISE MUSE | D14: ROTULO BODY SPLASH B BALM BIOFLORA | F14: EMBALAGEM | G14: ROTULO
B15: EMRT - BFBBBS04 | C15: ROTULO BODY SPLASH BIO BALM SKINLIGHT | D15: ROTULO BODY SPLASH B BALM BIOFLORA | F15: EMBALAGEM | G15: ROTULO
B16: EMRT - BFBBBS03 | C16: ROTULO BODY SPLASH BIO BALM ROSE ABSOLUT | D16: ROTULO BODY SPLASH B BALM BIOFLORA | F16: EMBALAGEM | G16: ROTULO
B17: EMRT - BFBBBS02 | C17: ROTULO BODY SPLASH BIO BALM INFINITY ROUGE | D17: ROTULO BODY SPLASH B BALM BIOFLORA | F17: EMBALAGEM | G17: ROTULO
B18: EMRT - BFBBBS01 | C18: ROTULO BODY SPLASH BIO BALM EUPHORIA PINK | D18: ROTULO BODY SPLASH B BALM BIOFLORA | F18: EMBALAGEM | G18: ROTULO
B19: EMRT - MRARBS05 | C19: ROTULO BODY SPLASH ASAD | D19: ROTULO BODY SPLASH ARABE MISS ROSE | F19: EMBALAGEM | G19: ROTULO
B20: EMRT - MRARBS04 | C20: ROTULO BODY SPLASH NECTAR DAS TAMARAS | D20: ROTULO BODY SPLASH ARABE MISS ROSE | F20: EMBALAGEM | G20: ROTULO
B21: EMRT - MRARBS03 | C21: ROTULO BODY SPLASH ECLIPSE DOURADO | D21: ROTULO BODY SPLASH ARABE MISS ROSE | F21: EMBALAGEM | G21: ROTULO
B22: EMRT - MRARBS02 | C22: ROTULO BODY SPLASH DEUSA DO NILO | D22: ROTULO BODY SPLASH ARABE MISS ROSE | F22: EMBALAGEM | G22: ROTULO | N22: Código | O22: Descrição | P22: Grupo
B23: EMFR - FR | C23: FRASCO LONGO PET CRISTAL 120 ML 24410 - SOROPACK | D23: ROTULO BODY SPLASH ARABE MISS ROSE | F23: EMBALAGEM | G23: FRASCO | N23: 14 | O23: FRASCO | P23: EMBALAGEM
B24: EMVL - VLBS01 | C24: VALVULA SPRAY LUXO - LEADPACK | D24: BODY SPLASH | F24: EMBALAGEM | G24: VALVULA | N24: 15 | O24: ROTULO | P24: EMBALAGEM
B25: EMTP - GLMKAM02 | C25: TAMPA FLIP TOP 24 ROSCA AZUL | D25: AGUA MICELAR - GLOW MAKE UP | F25: EMBALAGEM | G25: TAMPA | N25: 16 | O25: TAMPA | P25: EMBALAGEM
B26: EMTP - GLMKAM01 | C26: TAMPA FLIP TOP 24 ROSCA AMARELO 11878 | D26: TAMPA AGUA MICELAR GLOW MAKE UP | F26: EMBALAGEM | G26: TAMPA | N26: 17 | O26: SOBRETAMPA | P26: EMBALAGEM
B27: EMSL - MRARBS | C27: SLEEVE PARA BODY SPLASH | D27: BODY SPLASH MISS ROSE | F27: EMBALAGEM | G27: SLEEVE | N27: 18 | O27: CARTUCHO | P27: EMBALAGEM
B28: EMRT - MRARBS01 | C28: ROTULO BODY SPLASH AURORA IMPERIAL | D28: BODY SPLASH ARABE AURORA IMPERIAL MISS ROSE | F28: EMBALAGEM | G28: ROTULO | N28: 19 | O28: CELOFANE | P28: EMBALAGEM
B29: EMCX - MRARBS | C29: CAIXA DE EMBARQUE | D29: CAIXA BODY SPLASH ARABE | F29: EMBALAGEM | G29: CAIXA DE EMBARQUE | N29: 20 | O29: SLEEVE | P29: EMBALAGEM
B30: EMVL - KUBS | C30: VALVULA SPRAY 24410 - LION | D30: BODY SPLASH | F30: EMBALAGEM | G30: VALVULA | N30: 21 | O30: VALVULA | P30: EMBALAGEM
B31: EMFR - KUBPBA02 | C31: FRASCO PET 1L GRAVADO - BASE PARA PERFUME | D31: BASE PARA PERFUME | F31: EMBALAGEM | G31: FRASCO | N31: 32 | O31: CAIXA DE EMBARQUE | P31: EMBALAGEM
B32: EMVL - DPHNPC01 | C32: VALVULA SPRAY - LION PERFUME CAPILAR | D32: SPRAY CAPILAR DAPOP | F32: EMBALAGEM | G32: VALVULA | N32: 34 | O32: ETIQUETA | P32: EMBALAGEM
B33: EMVL - DPHNBS01 | C33: VALVULA SPRAY - LION BODY SPLASH | D33: BODY SPLASH HONEY DAPOP | F33: EMBALAGEM | G33: VALVULA

Sheet Sheet1
C2: MP 1 | D2: MP 2 | E2: MP 3 | F2: MP 4 | G2: MP 5 | H2: MP 6 | I2: MP 7 | J2: MP 8 | K2: MP 9 | L2: MP 10 | M2: MP 11 | N2: MP 12 | O2: MP 13 | P2: MP 14 | Q2: MP 15
B3: BFBBBS01 | C3: ALCOOL | D3: AGUA | E3: ESSENCIA | F3: DIETILFTALATO | G3: CONSERVANTE

Sheet TAB_FORMAS
A1: CAT3 | B1: Forma | C1: PalavrasChave
A2: SER | B2: Serum | C2: serum;firmador;concentrado
A3: AGU | B3: Agua | C3: agua;termal;micelar
A4: BRU | B4: Bruma | C4: bruma;nevoa;mist
A5: TON | B5: Tonico | C5: tonico;toner
A6: ESP | B6: Espuma | C6: espuma;mousse
A7: HID | B7: Hidratante | C7: hidratante;creme;locao;body lotion
A8: GEL | B8: Gel | C8: gel
A9: OLE | B9: Oleo | C9: oleo;oil
A10: MAN | B10: Manteiga | C10: manteiga;balsamo;butter
A11: SAB | B11: Sabonete liquido | C11: sabonete liquido;sabonete;gel de banho
A12: SBB | B12: Sabonete em barra | C12: barra
... A22: PRO | B22: Protetor solar | C22: protetor solar;fps;solar

Sheet TAB_CLIENTES
A1: Cliente | B1: CLI4
A2: AFEER OF ARABIAN | B2: AFEE
A3: AMEERATI
A4: BE MAGIC
A5: BIOFLORA
A6: BRIA BEAUTY
A7: CAMIE BEAUTY
A8: CURADERM
A9: DAPOP
A10: DYNASTY
A11: FEBELLA BEAUTY
A12: FILATO BENE
A13: GLOW MAKE UP
A14: GOTA ZEN
... A20: MAAKE
A21: MENELA | B21: MENE
A22: MISS ROSE
A23: MOUTIER
A24: PRO STYLE
A25: PURO EU
A26: ROSA RAINHA | B26: ROSA
A27: SAFIRA
A28: SEUNOURA | B28: SENR
A29: VELLARIS ESSENCE | B29: VELL
A30: WIKE MAKE
